Workbook

Sheet Dashboard
I3: Recommendation | J3: =IF($C$9>=C8,"Buy",IF($C$9<=0,"Hold","Sell")) -> Buy
B5: Company Overview | E5: Methodologies | I5: Key Statisitics | M5: Links
B6: Ticker | C6: ARCC | E6: DCF | F6: =Valuation!C31 -> 128.46401 | I6: IPO | M6: Financial Statements'!A1 | N6: ESG Guideline'!A1 | O6: 1
B7: Stock Exchange | C7: EGX30 | E7: P/E | F7: =Valuation!C46 -> 112.81179 | I7: Incorporated | M7: IS!A1 | N7: ESG Scorecard '!A1 | O7: =O6+1 -> 2
B8: Current Price | C8: =Valuation!K3 -> 73.45 | E8: EV/EBITDA | F8: =Valuation!C67 -> 114.29905 | I8: Chairman | M8: Revenue Bridge'!A1 | N8: ESG Integration'!A1 | O8: =O7+1 -> 3
B9: Target Price | C9: =Valuation!E74 -> 123.99143 | E9: Overall Valuation | F9: =SUM(F6:F8) -> 355.57485 | I9: Headquarters | M9: COGS Bridge'!A1 | N9: Elasticity Analysis'!A1 | O9: =O8+1 -> 4
B10: =IF(C10="","Nothing Yet",IF(C10>0,"Upside","Downside")) -> Upside | C10: =C9/C8-1 -> 0.68810662 | I10: Primary industry | M10: Assumptions!A1 | N10: Valuation!A1 | O10: =O9+1 -> 5
I11: Sector | M11: BS!A1 | O11: =O10+1 -> 6
M12: Debt!A1 | O12: =O11+1 -> 7
M13: Ratios!A1 | O13: =O12+1 -> 8

Sheet Financial Statements
B1: Figures in EGPmn | N1: Core | O1: CAGR | R1: Financial Statements'!A1
B2: Income Statement
D3: 2021 | E3: =D3+1 -> 2022 | F3: =E3+1 -> 2023 | G3: =F3+1 -> 2024 | H3: =G3+1 -> 2025 | I3: =H3+1 -> 2026 | J3: =I3+1 -> 2027 | K3: =J3+1 -> 2028 | L3: =K3+1 -> 2029 | M3: =L3+1 -> 2030 | O3: Historic | P3: Fcsted
B4: Net Sales | D4: =IS!C13 -> 2448.6314 | E4: =IS!D13 -> 4675.0028 | F4: =IS!E13 -> 6042.8313 | G4: =IS!F13 -> 8729.7828 | H4: =IS!G13 -> 12447.32 | I4: ='Revenue Bridge'!H15 -> 14726.167 | J4: ='Revenue Bridge'!I15 -> 16143.641 | K4: ='Revenue Bridge'!J15 -> 17268.587 | L4: ='Revenue Bridge'!K15 -> 18276.163 | M4: ='Revenue Bridge'!L15 -> 19302.88 | O4: =_xlfn.RRI(4,D4,H4) -> 0.50154417 | P4: =_xlfn.RRI(4,I4,M4) -> 0.069998327
B5: Cost of Sales | D5: =-IS!C25+IS!C20+IS!C21+IS!C22 -> -2024.7314 | E5: =-IS!D25+IS!D20+IS!D21+IS!D22 -> -3550.2143 | F5: =-IS!E25+IS!E20+IS!E21+IS!E22 -> -4512.007 | G5: =-IS!F25+IS!F20+IS!F21+IS!F22 -> -6390.0166 | H5: =-IS!G25+IS!G20+IS!G21+IS!G22 -> -7103.6073 | I5: =-'COGS Bridge'!I11 -> -8065.2624 | J5: =-'COGS Bridge'!J11 -> -8776.0602 | K5: =-'COGS Bridge'!K11 -> -9405.4201 | L5: =-'COGS Bridge'!L11 -> -9967.3074 | M5: =-'COGS Bridge'!M11 -> -10539.716 | O5: =_xlfn.RRI(4,D5,H5) -> 0.36860424 | P5: =_xlfn.RRI(4,I5,M5) -> 0.069184377
B6: Gross Profit | D6: =D4+D5 -> 423.89997 | E6: =E4+E5 -> 1124.7885 | F6: =F4+F5 -> 1530.8244 | G6: =G4+G5 -> 2339.7662 | H6: =H4+H5 -> 5343.7128 | I6: =I4+I5 -> 6660.9043 | J6: =J4+J5 -> 7367.5812 | K6: =K4+K5 -> 7863.1672 | ... M6: =M4+M5 -> 8763.1637 | O6: =_xlfn.RRI(4,D6,H6) -> 0.8842778 | P6: =_xlfn.RRI(4,I6,M6) -> 0.070981408
B7: Margin | D7: =IFERROR(D6/D4,0) -> 0.17311711 | E7: =IFERROR(E6/E4,0) -> 0.24059633 | F7: =IFERROR(F6/F4,0) -> 0.25332899 | G7: =IFERROR(G6/G4,0) -> 0.26802112 | H7: =IFERROR(H6/H4,0) -> 0.42930629 | I7: =IFERROR(I6/I4,0) -> 0.4523176 | J7: =IFERROR(J6/J4,0) -> 0.45637666 | K7: =IFERROR(K6/K4,0) -> 0.45534514 | ... M7: =IFERROR(M6/M4,0) -> 0.45398219
B8: General & Administrative Expenses | D8: =-IS!C37+IS!C35 -> -78.96535 | E8: =-IS!D37+IS!D35 -> -112.72108 | F8: =-IS!E37+IS!E35 -> -181.32399 | G8: =-IS!F37+IS!F35 -> -263.95244 | H8: =-IS!G37+IS!G35 -> -380.0087 | I8: =-IS!H37+IS!H35 -> -433.40615 | J8: =-IS!I37+IS!I35 -> -478.83741 | K8: =-IS!J37+IS!J35 -> -515.47492 | ... M8: =-IS!L37+IS!L35 -> -577.04951
B9: Gain on Disposal of Property, Plant, and Equipment | D9: =IS!C83 -> 0.12 | E9: =IS!D83 -> 0.2 | F9: =IS!E83 -> 0.087675 | G9: =IS!F83 -> 0 | H9: =IS!G83 -> 1.14 | I9: =IS!H83 -> 0 | J9: =IS!I83 -> 0 | K9: =IS!J83 -> 0 | ... M9: =IS!L83 -> 0
B10: Other Income | D10: =IS!C70 -> 46.323288 | E10: =IS!D70 -> 104.2275 | F10: =IS!E70 -> 14.913053 | G10: =IS!F70 -> 18.292936 | H10: =IS!G70 -> 53.339508 | I10: =IS!H70 -> 63.104868 | J10: =IS!I70 -> 69.179059 | K10: =IS!J70 -> 73.9997 | ... M10: =IS!L70 -> 82.717092
B11: Other Operating Income | D11: =-(IS!C44+IS!C54)-IS!C52 -> -7.368018 | E11: =-(IS!D44+IS!D54)-IS!D52 -> -112.63989 | F11: =-(IS!E44+IS!E54)-IS!E52 -> -19.965948 | G11: =-(IS!F44+IS!F54)-IS!F52 -> -54.946498 | H11: =-(IS!G44+IS!G54)-IS!G52 -> -78.10927 | I11: =-(IS!H44+IS!H54)-IS!H52 -> -90.708218 | J11: =-(IS!I44+IS!I54)-IS!I52 -> -99.439384 | K11: =-(IS!J44+IS!J54)-IS!J52 -> -106.36867 | ... M11: =-(IS!L44+IS!L54)-IS!L52 -> -118.89923
B12: EBITDA | D12: =D6+SUM(D8:D11) -> 384.00989 | E12: =E6+SUM(E8:E11) -> 1003.8551 | F12: =F6+SUM(F8:F11) -> 1344.5352 | G12: =G6+SUM(G8:G11) -> 2039.1602 | H12: =H6+SUM(H8:H11) -> 4940.0744 | I12: =I6+SUM(I8:I11) -> 6199.8949 | J12: =J6+SUM(J8:J11) -> 6858.4835 | K12: =K6+SUM(K8:K11) -> 7315.3233 | ... M12: =M6+SUM(M8:M11) -> 8149.932 | O12: =_xlfn.RRI(4,D12,H12) -> 0.89385955 | P12: =_xlfn.RRI(4,I12,M12) -> 0.070760683
B13: Margin | D13: =IFERROR(D12/D4,0) -> 0.15682634 | E13: =IFERROR(E12/E4,0) -> 0.21472823 | F13: =IFERROR(F12/F4,0) -> 0.22250086 | G13: =IFERROR(G12/G4,0) -> 0.23358659 | H13: =IFERROR(H12/H4,0) -> 0.39687855 | I13: =IFERROR(I12/I4,0) -> 0.42101213 | J13: =IFERROR(J12/J4,0) -> 0.42484117 | K13: =IFERROR(K12/K4,0) -> 0.42362025 | ... M13: =IFERROR(M12/M4,0) -> 0.42221327
B14: Depreciation | D14: =-(IS!C20+IS!C35) -> -217.92949 | E14: =-(IS!D20+IS!D35) -> -208.21501 | F14: =-(IS!E20+IS!E35) -> -215.37694 | G14: =-(IS!F20+IS!F35) -> -221.56286 | H14: =-(IS!G20+IS!G35) -> -259.08968 | I14: =BS!H91 -> -318.57094 | J14: =BS!I91 -> -328.89888 | K14: =BS!J91 -> -344.2128 | L14: =BS!K91 -> -358.03881 | M14: =BS!L91 -> -376.41643
B15: Amortization | D15: =-(IS!C21+IS!C22) -> -40.527821 | E15: =-(IS!D21+IS!D22) -> -33.64381 | F15: =-(IS!E21+IS!E22) -> -35.047582 | G15: =-(IS!F21+IS!F22) -> -35.238663 | H15: =-(IS!G21+IS!G22) -> -30.681613 | I15: =BS!H137+BS!H144+BS!H158 -> -24.782969 | J15: =BS!I137+BS!I144+BS!I158 -> -26.125423 | K15: =BS!J137+BS!J144+BS!J158 -> -26.35488 | L15: =BS!K137+BS!K144+BS!K158 -> 2.4018247 | M15: =BS!L137+BS!L144+BS!L158 -> 0
B16: Total Depreciation & Amortization | D16: =SUM(D14:D15) -> -258.45731 | E16: =SUM(E14:E15) -> -241.85882 | F16: =SUM(F14:F15) -> -250.42452 | G16: =SUM(G14:G15) -> -256.80153 | H16: =SUM(H14:H15) -> -289.7713 | I16: =SUM(I14:I15) -> -343.35391 | J16: =SUM(J14:J15) -> -355.0243 | K16: =SUM(K14:K15) -> -370.56768 | ... M16: =SUM(M14:M15) -> -376.41643
B17: EBIT | D17: =D12+D16 -> 125.55258 | E17: =E12+E16 -> 761.99625 | F17: =F12+F16 -> 1094.1106 | G17: =G12+G16 -> 1782.3587 | H17: =H12+H16 -> 4650.3031 | I17: =I12+I16 -> 5856.5409 | J17: =J12+J16 -> 6503.4592 | K17: =K12+K16 -> 6944.7556 | ... M17: =M12+M16 -> 7773.5156 | O17: =_xlfn.RRI(4,D17,H17) -> 1.4669702 | P17: =_xlfn.RRI(4,I17,M17) -> 0.073356703
B18: Margin | D18: =IFERROR(D17/D4,0) -> 0.051274594 | E18: =IFERROR(E17/E4,0) -> 0.16299375 | F18: =IFERROR(F17/F4,0) -> 0.18105927 | G18: =IFERROR(G17/G4,0) -> 0.20416988 | H18: =IFERROR(H17/H4,0) -> 0.37359874 | I18: =IFERROR(I17/I4,0) -> 0.39769623 | J18: =IFERROR(J17/J4,0) -> 0.40284958 | K18: =IFERROR(K17/K4,0) -> 0.40216119 | ... M18: =IFERROR(M17/M4,0) -> 0.40271274
B19: Finance Costs | D19: =-IS!C79 -> -70.126214 | E19: =-IS!D79 -> -58.08122 | F19: =-IS!E79 -> -76.979253 | G19: =-IS!F79 -> -91.188916 | H19: =-IS!G79 -> -49.841733 | I19: =-IS!H79 -> -98.124734 | J19: =-IS!I79 -> -91.568676 | K19: =-IS!J79 -> -71.755428 | ... M19: =-IS!L79 -> -34.246877
B20: FX exchange | D20: =-IS!C84 -> -1.060989 | E20: =-IS!D84 -> -192.05848 | F20: =-IS!E84 -> -115.14417 | G20: =-IS!F84 -> -243.81213 | H20: =-IS!G84 -> -101.57824 | I20: =-IS!H84 -> 0 | J20: =-IS!I84 -> 0 | K20: =-IS!J84 -> 0 | ... M20: =-IS!L84 -> 0
B21: Interest Income | D21: =IS!C66 -> 0.743822 | E21: =IS!D66 -> 9.96778 | F21: =IS!E66 -> 30.813502 | G21: =IS!F66 -> 56.458493 | H21: =IS!G66 -> 226.27478 | I21: =IS!H66 -> 267.70101 | J21: =IS!I66 -> 293.46871 | K21: =IS!J66 -> 313.91864 | ... M21: =IS!L66 -> 350.89922
B22: Investment in a Joint Venture | D22: =IS!C63 -> 0.068872 | E22: =IS!D63 -> 0.047164 | F22: =IS!E63 -> -2.569276 | G22: =IS!F63 -> 2.05 | H22: =IS!G63 -> 0 | I22: =IS!H63 -> 0 | J22: =IS!I63 -> 0 | K22: =IS!J63 -> 0 | ... M22: =IS!L63 -> 0
B23: Non recurring Items
B24: Bad Debt | D24: =IS!C94 -> 0 | E24: =IS!D94 -> -0.00681 | F24: =IS!E94 -> 0 | G24: =IS!F94 -> 0 | H24: =IS!G94 -> 0 | I24: =IS!H94 -> 0 | J24: =IS!I94 -> 0 | K24: =IS!J94 -> 0 | ... M24: =IS!L94 -> 0
B25: EBT | D25: =D17+SUM(D19:D24) -> 55.17807 | E25: =E17+SUM(E19:E24) -> 521.86468 | F25: =F17+SUM(F19:F24) -> 930.23143 | G25: =G17+SUM(G19:G24) -> 1505.8661 | H25: =H17+SUM(H19:H24) -> 4725.1579 | I25: =I17+SUM(I19:I24) -> 6026.1172 | J25: =J17+SUM(J19:J24) -> 6705.3592 | K25: =K17+SUM(K19:K24) -> 7186.9188 | ... M25: =M17+SUM(M19:M24) -> 8090.168 | O25: =_xlfn.RRI(4,D25,H25) -> 2.0420227 | P25: =_xlfn.RRI(4,I25,M25) -> 0.076415619
B26: Margin | D26: =IFERROR(D25/D4,0) -> 0.02253425 | E26: =IFERROR(E25/E4,0) -> 0.11162874 | F26: =IFERROR(F25/F4,0) -> 0.15393967 | G26: =IFERROR(G25/G4,0) -> 0.17249755 | H26: =IFERROR(H25/H4,0) -> 0.37961247 | I26: =IFERROR(I25/I4,0) -> 0.40921153 | J26: =IFERROR(J25/J4,0) -> 0.41535606 | K26: =IFERROR(K25/K4,0) -> 0.41618453 | ... M26: =IFERROR(M25/M4,0) -> 0.41911715
B27: Income Taxes | D27: =-IS!C91 -> -20.988687 | E27: =-IS!D91 -> -162.87764 | F27: =-IS!E91 -> -232.7328 | G27: =-IS!F91 -> -345.731 | H27: =-IS!G91 -> -1125.4677 | I27: =-IS!H91 -> -1355.8764 | J27: =-IS!I91 -> -1508.7058 | K27: =-IS!J91 -> -1617.0567 | ... M27: =-IS!L91 -> -1820.2878
B28: Net Profit | D28: =D25+D27 -> 34.189383 | E28: =E25+E27 -> 358.98704 | F28: =F25+F27 -> 697.49863 | G28: =G25+G27 -> 1160.1351 | H28: =H25+H27 -> 3599.6902 | I28: =I25+I27 -> 4670.2408 | J28: =J25+J27 -> 5196.6534 | K28: =K25+K27 -> 5569.8621 | ... M28: =M25+M27 -> 6269.8802 | O28: =_xlfn.RRI(4,D28,H28) -> 2.2032694 | P28: =_xlfn.RRI(4,I28,M28) -> 0.076415619
B29: Margin | D29: =IFERROR(D28/D4,0) -> 0.01396265 | E29: =IFERROR(E28/E4,0) -> 0.076788625 | F29: =IFERROR(F28/F4,0) -> 0.1154258 | G29: =IFERROR(G28/G4,0) -> 0.13289393 | H29: =IFERROR(H28/H4,0) -> 0.28919399 | I29: =IFERROR(I28/I4,0) -> 0.31713893 | J29: =IFERROR(J28/J4,0) -> 0.32190094 | K29: =IFERROR(K28/K4,0) -> 0.32254301 | ... M29: =IFERROR(M28/M4,0) -> 0.32481579
B31: Profit Attributable
B32: Owners of the Parent Company | D32: 34.18181 | E32: 358.98648 | F32: 697.48874 | G32: 1160.1294 | H32: 3599.5859 | I32: =I28-I33 -> 4670.1366 | J32: =J28-J33 -> 5196.5491 | K32: =K28-K33 -> 5569.7578 | L32: =L28-L33 -> 5930.9319 | M32: =M28-M33 -> 6269.7759
B33: Non-Controlling Interests | D33: 0.007573 | E33: 0.00056 | F33: 0.009889 | G33: 0.005711 | H33: 0.104284 | I33: 0.104284 | J33: 0.104284 | K33: 0.104284 | L33: 0.104284 | M33: 0.104284
B34: Total | D34: =SUM(D32:D33) -> 34.189383 | E34: =SUM(E32:E33) -> 358.98704 | F34: =SUM(F32:F33) -> 697.49863 | G34: =SUM(G32:G33) -> 1160.1351 | H34: =SUM(H32:H33) -> 3599.6902 | I34: =SUM(I32:I33) -> 4670.2408 | J34: =SUM(J32:J33) -> 5196.6534 | K34: =SUM(K32:K33) -> 5569.8621 | ... M34: =SUM(M32:M33) -> 6269.8802
B35: Checker | D35: =D34=D28 -> FALSE | E35: =E34=E28 -> TRUE | F35: =F34=F28 -> TRUE | G35: =G34=G28 -> TRUE | H35: =H34=H28 -> TRUE | I35: =I34=I28 -> TRUE | J35: =J34=J28 -> TRUE | K35: =K34=K28 -> TRUE | ... M35: =M34=M28 -> TRUE
D36: =D34-D28 -> -2.4868996e-13 | E36: =E34-E28 -> 0 | F36: =F34-F28 -> 0 | G36: =G34-G28 -> 0 | H36: =H34-H28 -> 0
B38: Balance Sheet Statement
D39: =D3 -> 2021 | E39: =E3 -> 2022 | F39: =F3 -> 2023 | G39: =G3 -> 2024 | H39: =H3 -> 2025 | I39: =I3 -> 2026 | J39: =J3 -> 2027 | K39: =K3 -> 2028 | ... M39: =M3 -> 2030
B40: Non-Current Assets
B41: Property, Plant, and Equipment | D41: =BS!C121 -> 2019.9452 | E41: =BS!D121 -> 1839.1046 | F41: =BS!E121 -> 1683.6071 | G41: =BS!F121 -> 1669.6306 | H41: =BS!G121 -> 2522.3235 | I41: =BS!H121 -> 2826.9947 | J41: =BS!I121 -> 2752.0964 | K41: =BS!J121 -> 2679.5839 | ... M41: =BS!L121 -> 2536.3893
B42: Assets Under Construction | D42: =BS!C128 -> 3.261312 | E42: =BS!D128 -> 3.952133 | F42: =BS!E128 -> 2.426563 | G42: =BS!F128 -> 706.85563 | H42: =BS!G128 -> 391.54375 | I42: =BS!H128 -> 0 | J42: =BS!I128 -> 0 | K42: =BS!J128 -> 0 | ... M42: =BS!L128 -> 0
...

Sheet IS
B2: Footnotes BD | C2: 2021 | D2: =C2+1 -> 2022 | E2: =D2+1 -> 2023 | F2: =E2+1 -> 2024 | G2: =F2+1 -> 2025 | H2: =G2+1 -> 2026 | I2: =H2+1 -> 2027 | J2: =I2+1 -> 2028 | K2: =J2+1 -> 2029 | L2: =K2+1 -> 2030
B4: Revenue
B5: Local
B6: Sales | C6: 2054.1196 | D6: 3821.5448 | E6: 3906.434 | F6: 4703.4792 | G6: 8350.4546 | H6: ='Revenue Bridge'!H6 -> 10320.725 | I6: ='Revenue Bridge'!I6 -> 10902.035 | J6: ='Revenue Bridge'!J6 -> 11738.811 | K6: ='Revenue Bridge'!K6 -> 12495.316 | L6: ='Revenue Bridge'!L6 -> 13301.991
B7: Services | C7: 92.559521 | D7: 103.05889 | E7: 82.820228 | F7: 179.82523 | G7: 281.86355 | H7: ='Revenue Bridge'!H7 -> 290.31945 | I7: ='Revenue Bridge'!I7 -> 299.02904 | J7: ='Revenue Bridge'!J7 -> 307.99991 | K7: ='Revenue Bridge'!K7 -> 317.2399 | L7: ='Revenue Bridge'!L7 -> 326.7571
B8: Total Local Sales | C8: =SUM(C6:C7) -> 2146.6791 | D8: =SUM(D6:D7) -> 3924.6037 | E8: =SUM(E6:E7) -> 3989.2543 | F8: =SUM(F6:F7) -> 4883.3045 | G8: =SUM(G6:G7) -> 8632.3182 | H8: =SUM(H6:H7) -> 10611.044 | I8: =SUM(I6:I7) -> 11201.064 | J8: =SUM(J6:J7) -> 12046.811 | ... L8: =SUM(L6:L7) -> 13628.748
B9: Export
B10: Sales | C10: 237.80973 | D10: 667.51415 | E10: 1622.381 | F10: 3222.781 | G10: 3356.4224 | H10: ='Revenue Bridge'!H10 -> 3642.7859 | I10: ='Revenue Bridge'!I10 -> 4456.0709 | J10: ='Revenue Bridge'!J10 -> 4720.6741 | K10: ='Revenue Bridge'!K10 -> 4947.472 | L10: ='Revenue Bridge'!L10 -> 5142.5129
B11: Services | C11: 64.142523 | D11: 82.884935 | E11: 431.19609 | F11: 623.6973 | G11: 458.57954 | H11: ='Revenue Bridge'!H11 -> 472.33693 | I11: ='Revenue Bridge'!I11 -> 486.50704 | J11: ='Revenue Bridge'!J11 -> 501.10225 | K11: ='Revenue Bridge'!K11 -> 516.13532 | L11: ='Revenue Bridge'!L11 -> 531.61938
B12: Total Export Sales | C12: =SUM(C10:C11) -> 301.95225 | D12: =SUM(D10:D11) -> 750.39909 | E12: =SUM(E10:E11) -> 2053.5771 | F12: =SUM(F10:F11) -> 3846.4783 | G12: =SUM(G10:G11) -> 3815.0019 | H12: =SUM(H10:H11) -> 4115.1228 | I12: =SUM(I10:I11) -> 4942.5779 | J12: =SUM(J10:J11) -> 5221.7763 | ... L12: =SUM(L10:L11) -> 5674.1322
B13: Total Revenue | C13: =C8+C12 -> 2448.6314 | D13: =D8+D12 -> 4675.0028 | E13: =E8+E12 -> 6042.8313 | F13: =F8+F12 -> 8729.7828 | G13: =G8+G12 -> 12447.32 | H13: =H8+H12 -> 14726.167 | I13: =I8+I12 -> 16143.641 | J13: =J8+J12 -> 17268.587 | ... L13: =L8+L12 -> 19302.88
B14: rev YOY | D14: =('Financial Statements'!E4-'Financial Statements'!D4)/'Financial Statements'!D4 -> 0.90923097 | E14: =('Financial Statements'!F4-'Financial Statements'!E4)/'Financial Statements'!E4 -> 0.29258346 | F14: =('Financial Statements'!G4-'Financial Statements'!F4)/'Financial Statements'!F4 -> 0.44465108 | G14: =('Financial Statements'!H4-'Financial Statements'!G4)/'Financial Statements'!G4 -> 0.42584533 | H14: =('Financial Statements'!I4-'Financial Statements'!H4)/'Financial Statements'!H4 -> 0.18307931 | I14: =('Financial Statements'!J4-'Financial Statements'!I4)/'Financial Statements'!I4 -> 0.096255509 | J14: =('Financial Statements'!K4-'Financial Statements'!J4)/'Financial Statements'!J4 -> 0.069683522 | K14: =('Financial Statements'!L4-'Financial Statements'!K4)/'Financial Statements'!K4 -> 0.058347329 | L14: =('Financial Statements'!M4-'Financial Statements'!L4)/'Financial Statements'!L4 -> 0.056177916
B15: Services % of total | C15: =(C7+C11)/C13 -> 0.063995768 | D15: =(D7+D11)/D13 -> 0.039774056 | E15: =(E7+E11)/E13 -> 0.085062165 | F15: =(F7+F11)/F13 -> 0.092043816 | G15: =(G7+G11)/G13 -> 0.059486145 | H15: =(H7+H11)/H13 -> 0.051789199 | I15: =(I7+I11)/I13 -> 0.048659163 | J15: =(J7+J11)/J13 -> 0.046853987 | ... L15: =(L7+L11)/L13 -> 0.044468829
B16: Sales % of total | C16: =(C6+C10)/C13 -> 0.93600423 | D16: =(D6+D10)/D13 -> 0.96022594 | E16: =(E6+E10)/E13 -> 0.91493784 | F16: =(F6+F10)/F13 -> 0.90795618 | G16: =(G6+G10)/G13 -> 0.94051385 | H16: =(H6+H10)/H13 -> 0.9482108 | I16: =(I6+I10)/I13 -> 0.95134084 | J16: =(J6+J10)/J13 -> 0.95314601 | ... L16: =(L6+L10)/L13 -> 0.95553117
B18: Cost of Sales
B19: Raw materials | C19: 1705.51 | D19: 3118.7494 | E19: 3779.8177 | F19: 5225.344 | G19: 5698.1847 | H19: ='COGS Bridge'!I5 -> 6474.3241 | I19: ='COGS Bridge'!J5 -> 7008.5278 | J19: ='COGS Bridge'!K5 -> 7494.7175 | K19: ='COGS Bridge'!L5 -> 7938.1413 | L19: ='COGS Bridge'!M5 -> 8400.9751
B20: Depreciation | C20: 215.82438 | D20: 205.95811 | E20: 212.76065 | F20: 217.7172 | G20: 254.76555 | H20: ='COGS Bridge'!I6 -> 0 | I20: ='COGS Bridge'!J6 -> 0 | J20: ='COGS Bridge'!K6 -> 0 | K20: ='COGS Bridge'!L6 -> 0 | L20: ='COGS Bridge'!M6 -> 0
B21: Amortization of Licenses, Intangible assets | C21: 34.624973 | D21: 28.156249 | E21: 28.156249 | F21: 28.156249 | G21: 28.156249 | H21: ='COGS Bridge'!I7 -> 0 | I21: ='COGS Bridge'!J7 -> 0 | J21: ='COGS Bridge'!K7 -> 0 | K21: ='COGS Bridge'!L7 -> 0 | L21: ='COGS Bridge'!M7 -> 0
B22: Amortization of right of use | C22: 5.902848 | D22: 5.487561 | E22: 6.891333 | F22: 7.082414 | G22: 2.525364 | H22: ='COGS Bridge'!I8 -> 0 | I22: ='COGS Bridge'!J8 -> 0 | J22: ='COGS Bridge'!K8 -> 0 | K22: ='COGS Bridge'!L8 -> 0 | L22: ='COGS Bridge'!M8 -> 0
B23: Transportation costs | C23: 114.65141 | D23: 165.49009 | E23: 498.18933 | F23: 792.24221 | G23: 764.27933 | H23: ='COGS Bridge'!I9 -> 865.1642 | I23: ='COGS Bridge'!J9 -> 961.19743 | J23: ='COGS Bridge'!K9 -> 1039.0544 | K23: ='COGS Bridge'!L9 -> 1103.4758 | L23: ='COGS Bridge'!M9 -> 1163.0635
B24: Overhead costs | C24: 204.57001 | D24: 265.97482 | E24: 233.99995 | F24: 372.4304 | G24: 641.14321 | H24: ='COGS Bridge'!I10 -> 725.77411 | I24: ='COGS Bridge'!J10 -> 806.33504 | J24: ='COGS Bridge'!K10 -> 871.64818 | K24: ='COGS Bridge'!L10 -> 925.69036 | L24: ='COGS Bridge'!M10 -> 975.67764
B25: Total | C25: =SUM(C19:C24) -> 2281.0836 | D25: =SUM(D19:D24) -> 3789.8162 | E25: =SUM(E19:E24) -> 4759.8152 | F25: =SUM(F19:F24) -> 6642.9725 | G25: =SUM(G19:G24) -> 7389.0544 | H25: =SUM(H19:H24) -> 8065.2624 | I25: =SUM(I19:I24) -> 8776.0602 | J25: =SUM(J19:J24) -> 9405.4201 | ... L25: =SUM(L19:L24) -> 10539.716
B26: cost YOY | D26: =('Financial Statements'!E5-'Financial Statements'!D5)/'Financial Statements'!D5 -> 0.75342484 | E26: =('Financial Statements'!F5-'Financial Statements'!E5)/'Financial Statements'!E5 -> 0.27091116 | F26: =('Financial Statements'!G5-'Financial Statements'!F5)/'Financial Statements'!F5 -> 0.4162249 | G26: =('Financial Statements'!H5-'Financial Statements'!G5)/'Financial Statements'!G5 -> 0.11167274 | H26: =('Financial Statements'!I5-'Financial Statements'!H5)/'Financial Statements'!H5 -> 0.13537561 | I26: =('Financial Statements'!J5-'Financial Statements'!I5)/'Financial Statements'!I5 -> 0.088130769 | J26: =('Financial Statements'!K5-'Financial Statements'!J5)/'Financial Statements'!J5 -> 0.071713254 | K26: =('Financial Statements'!L5-'Financial Statements'!K5)/'Financial Statements'!K5 -> 0.059740804 | L26: =('Financial Statements'!M5-'Financial Statements'!L5)/'Financial Statements'!L5 -> 0.057428635
B28: General & Administrative Expenses
B29: Professional services | C29: 15.94042 | D29: 21.611801 | E29: 23.08047 | F29: 27.516804 | G29: 29.752555 | H29: =G29*(1+Assumptions!J8) -> 33.679892 | I29: =H29*(1+Assumptions!K8) -> 37.41836 | J29: =I29*(1+Assumptions!L8) -> 40.449247 | K29: =J29*(1+Assumptions!M8) -> 42.957101 | L29: =K29*(1+Assumptions!N8) -> 45.276784
B30: Salaries and wages | C30: 29.372277 | D30: 37.393849 | E30: 74.139823 | F30: 124.88201 | G30: 178.98118 | H30: =G30*(1+Assumptions!J8) -> 202.6067 | I30: =H30*(1+Assumptions!K8) -> 225.09604 | J30: =I30*(1+Assumptions!L8) -> 243.32882 | K30: =J30*(1+Assumptions!M8) -> 258.41521 | L30: =K30*(1+Assumptions!N8) -> 272.36963
B31: Security and cleaning services | C31: 1.415022 | D31: 1.410636 | E31: 2.428688 | F31: 4.738183 | G31: 3.2704 | H31: =G31*(1+Assumptions!J8) -> 3.7020928 | I31: =H31*(1+Assumptions!K8) -> 4.1130251 | J31: =I31*(1+Assumptions!L8) -> 4.4461801 | K31: =J31*(1+Assumptions!M8) -> 4.7218433 | L31: =K31*(1+Assumptions!N8) -> 4.9768228
B32: Rentals | C32: 0.780775 | D32: 0.131736 | E32: 0.502419 | F32: 2.110584 | G32: 3.132247 | H32: =G32*(1+10%) -> 3.4454717 | I32: =H32*(1+10%) -> 3.7900189 | J32: =I32*(1+10%) -> 4.1690208 | K32: =J32*(1+10%) -> 4.5859228 | L32: =K32*(1+10%) -> 5.0445151
B33: Transportation costs | C33: 1.768887 | D33: 3.503839 | E33: 7.153216 | F33: 12.440064 | G33: 9.713478 | H33: =G33*(1+Assumptions!J8) -> 10.995657 | I33: =H33*(1+Assumptions!K8) -> 12.216175 | J33: =I33*(1+Assumptions!L8) -> 13.205685 | K33: =J33*(1+Assumptions!M8) -> 14.024438 | L33: =K33*(1+Assumptions!N8) -> 14.781757
B34: Advertising | C34: 1.240353 | D34: 2.221255 | E34: 3.401355 | F34: 4.677984 | G34: 7.803161 | H34: =H38*'Financial Statements'!I4 -> 7.8912356 | I34: =I38*'Financial Statements'!J4 -> 8.6508105 | J34: =J38*'Financial Statements'!K4 -> 9.2536294 | K34: =K38*'Financial Statements'!L4 -> 9.793554 | L34: =L38*'Financial Statements'!M4 -> 10.343735
B35: Depreciation | C35: 2.10511 | D35: 2.256901 | E35: 2.61629 | F35: 3.84566 | G35: 4.324134
B36: Other expenses | C36: 28.447616 | D36: 46.447966 | E36: 70.618015 | F36: 87.586815 | G36: 147.35568 | H36: =H39*'Financial Statements'!I4 -> 171.0851 | I36: =I39*'Financial Statements'!J4 -> 187.55298 | J36: =J39*'Financial Statements'!K4 -> 200.62233 | K36: =K39*'Financial Statements'!L4 -> 212.32811 | L36: =L39*'Financial Statements'!M4 -> 224.25626
B37: Total | C37: =IF('Financial Statements'!$N$1="Core",SUM(IS!C29:C36),SUM(IS!C29:C36,IS!C40)) -> 81.07046 | D37: =IF('Financial Statements'!$N$1="Core",SUM(IS!D29:D36),SUM(IS!D29:D36,IS!D40)) -> 114.97798 | E37: =IF('Financial Statements'!$N$1="Core",SUM(IS!E29:E36),SUM(IS!E29:E36,IS!E40)) -> 183.94028 | F37: =IF('Financial Statements'!$N$1="Core",SUM(IS!F29:F36),SUM(IS!F29:F36,IS!F40)) -> 267.7981 | G37: =IF('Financial Statements'!$N$1="Core",SUM(IS!G29:G36),SUM(IS!G29:G36,IS!G40)) -> 384.33283 | H37: =IF('Financial Statements'!$N$1="Core",SUM(IS!H29:H36),SUM(IS!H29:H36,IS!H40)) -> 433.40615 | I37: =IF('Financial Statements'!$N$1="Core",SUM(IS!I29:I36),SUM(IS!I29:I36,IS!I40)) -> 478.83741 | J37: =IF('Financial Statements'!$N$1="Core",SUM(IS!J29:J36),SUM(IS!J29:J36,IS!J40)) -> 515.47492 | ... L37: =IF('Financial Statements'!$N$1="Core",SUM(IS!L29:L36),SUM(IS!L29:L36,IS!L40)) -> 577.04951
B38: Advertising % of sales | C38: =C34/'Financial Statements'!D4 -> 0.00050654951 | D38: =D34/'Financial Statements'!E4 -> 0.00047513447 | E38: =E34/'Financial Statements'!F4 -> 0.00056287439 | F38: =F34/'Financial Statements'!G4 -> 0.00053586488 | G38: =G34/'Financial Statements'!H4 -> 0.00062689486 | H38: =MEDIAN(C38:G38) -> 0.00053586488 | I38: =H38 -> 0.00053586488 | J38: =I38 -> 0.00053586488 | K38: =J38 -> 0.00053586488 | L38: =K38 -> 0.00053586488
B39: Other expenses % of sales | C39: =C36/'Financial Statements'!D4 -> 0.011617762 | D39: =D36/'Financial Statements'!E4 -> 0.0099353878 | E39: =E36/'Financial Statements'!F4 -> 0.011686246 | F39: =F36/'Financial Statements'!G4 -> 0.010033104 | G39: =G36/'Financial Statements'!H4 -> 0.011838346 | H39: =MEDIAN(C39:G39) -> 0.011617762 | I39: =H39 -> 0.011617762 | J39: =I39 -> 0.011617762 | K39: =J39 -> 0.011617762 | L39: =K39 -> 0.011617762
B40: Carbon & CBAM Compliance Costs | C40: 0 | D40: 0 | E40: 0 | F40: 0 | G40: 0 | H40: =IF('Financial Statements'!$N$1="Core",0,'ESG Integration'!I87) -> 0 | I40: =IF('Financial Statements'!$N$1="Core",0,'ESG Integration'!J87) -> 0 | J40: =IF('Financial Statements'!$N$1="Core",0,'ESG Integration'!K87) -> 0 | K40: =IF('Financial Statements'!$N$1="Core",0,'ESG Integration'!L87) -> 0 | L40: =IF('Financial Statements'!$N$1="Core",0,'ESG Integration'!M87) -> 0
B42: Provisions
B43: Beg. balance | C43: 18.500287 | D43: =C46 -> 25.797396 | E43: =D46 -> 63.871019 | F43: =E46 -> 54.445334 | G43: =F46 -> 77.899139 | H43: =G46 -> 111.68412 | I43: =H46 -> 199.16177 | J43: =I46 -> 294.60036 | K43: =J46 -> 396.20126 | L43: =K46 -> 503.22504
B44: Formed during the year | C44: 7.368018 | D44: 111.93989 | E44: 15.220195 | F44: 56.05295 | G44: 74.505707 | H44: =H47*'Financial Statements'!I4 -> 88.14616 | I44: =I47*'Financial Statements'!J4 -> 96.630714 | J44: =J47*'Financial Statements'!K4 -> 103.36428 | K44: =K47*'Financial Statements'!L4 -> 109.39531 | L44: =L47*'Financial Statements'!M4 -> 115.54091
B45: Used during year | C45: -0.070909 | D45: -73.866262 | E45: -24.64588 | F45: -32.599145 | G45: -40.72073 | H45: =-H47*H43 -> -0.66850567 | I45: =-I47*I43 -> -1.1921191 | J45: =-J47*J43 -> -1.7633843 | K45: =-K47*K43 -> -2.371535 | L45: =-L47*L43 -> -3.0121454
...

Sheet BS
B2: Footnotes BD | C2: 2021 | D2: =C2+1 -> 2022 | E2: =D2+1 -> 2023 | F2: =E2+1 -> 2024 | G2: =F2+1 -> 2025 | H2: =G2+1 -> 2026 | I2: =H2+1 -> 2027 | J2: =I2+1 -> 2028 | K2: =J2+1 -> 2029 | L2: =K2+1 -> 2030
B3: Assets BD
B4: Fixed Assets
B5: Beg. Balance
B6: Freehold Land | C6: 50.243436 | D6: =C54 -> 50.243436 | E6: =D54 -> 50.243436 | F6: =E54 -> 50.243436 | G6: =F54 -> 50.243436 | H6: =G54 -> 50.243436 | I6: =H54 -> 50.243436 | J6: =I54 -> 50.243436 | K6: =J54 -> 50.243436 | L6: =K54 -> 50.243436
B7: Buildings | C7: 636.36164 | D7: =C55 -> 662.06626 | E7: =D55 -> 669.65322 | F7: =E55 -> 695.14882 | G7: =F55 -> 731.93125 | H7: =G55 -> 914.33184 | I7: =H55 -> 1018.0241 | J7: =I55 -> 1131.6974 | K7: =J55 -> 1253.2918 | L7: =K55 -> 1381.9809
B8: Vehicles | C8: 46.283623 | D8: =C56 -> 47.674756 | E8: =D56 -> 61.176691 | F8: =E56 -> 67.485657 | G8: =F56 -> 182.24758 | H8: =G56 -> 239.96017 | I8: =H56 -> 306.53404 | J8: =I56 -> 379.51602 | K8: =J56 -> 457.58364 | L8: =K56 -> 540.20629
B9: Machinery & Equipment | C9: 2875.1717 | D9: =C57 -> 2882.4983 | E9: =D57 -> 2886.6432 | F9: =E57 -> 2903.4066 | G9: =F57 -> 2942.8895 | H9: =G57 -> 3798.0515 | I9: =H57 -> 4236.0496 | J9: =I57 -> 4286.9753 | K9: =J57 -> 4341.4498 | L9: =K57 -> 4399.1027
B10: Furniture & Fixtures | C10: 15.765021 | D10: =C58 -> 15.836471 | E10: =D58 -> 15.892264 | F10: =E58 -> 17.375697 | G10: =F58 -> 20.188085 | H10: =G58 -> 22.238758 | I10: =H58 -> 24.516921 | J10: =I58 -> 27.01437 | K10: =J58 -> 29.685851 | L10: =K58 -> 32.513204
B11: Other Installations | C11: 303.17949 | D11: =C59 -> 303.43283 | E11: =D59 -> 304.06282 | F11: =E59 -> 308.45338 | G11: =F59 -> 320.11178 | H11: =G59 -> 327.44967 | I11: =H59 -> 334.01992 | J11: =I59 -> 341.22259 | K11: =J59 -> 348.92717 | L11: =K59 -> 357.0813
B12: Computers & Software | C12: 21.679132 | D12: =C60 -> 22.362299 | E12: =D60 -> 23.5171 | F12: =E60 -> 28.093778 | G12: =F60 -> 30.182102 | H12: =G60 -> 37.134556 | I12: =H60 -> 43.26405 | J12: =I60 -> 49.983542 | K12: =J60 -> 57.171271 | L12: =K60 -> 64.778385
B13: Total | C13: =SUM(C6:C12) -> 3948.684 | D13: =SUM(D6:D12) -> 3984.1144 | E13: =SUM(E6:E12) -> 4011.1887 | F13: =SUM(F6:F12) -> 4070.2074 | G13: =SUM(G6:G12) -> 4277.7937 | H13: =SUM(H6:H12) -> 5389.41 | I13: =SUM(I6:I12) -> 6012.6521 | J13: =SUM(J6:J12) -> 6266.6527 | ... L13: =SUM(L6:L12) -> 6825.9062
B15: Additions
B16: =B6 -> Freehold Land | C16: 0 | D16: 0 | E16: 0 | F16: 0 | G16: 0 | H16: =H25*'Financial Statements'!I$4 -> 0 | I16: =I25*'Financial Statements'!J$4 -> 0 | J16: =J25*'Financial Statements'!K$4 -> 0 | K16: =K25*'Financial Statements'!L$4 -> 0 | L16: =L25*'Financial Statements'!M$4 -> 0
B17: =B7 -> Buildings | C17: 25.704619 | D17: 7.586965 | E17: 25.495598 | F17: 36.782424 | G17: 182.4006 | H17: =H26*'Financial Statements'!I$4 -> 103.69229 | I17: =I26*'Financial Statements'!J$4 -> 113.67325 | J17: =J26*'Financial Statements'!K$4 -> 121.5944 | K17: =K26*'Financial Statements'!L$4 -> 128.68911 | L17: =L26*'Financial Statements'!M$4 -> 135.9186
B18: =B8 -> Vehicles | C18: 1.831833 | D18: 13.501935 | E18: 7.080896 | F18: 114.76192 | G18: 57.878966 | H18: =H27*'Financial Statements'!I$4 -> 66.573874 | I18: =I27*'Financial Statements'!J$4 -> 72.981976 | J18: =J27*'Financial Statements'!K$4 -> 78.067617 | K18: =K27*'Financial Statements'!L$4 -> 82.622654 | L18: =L27*'Financial Statements'!M$4 -> 87.264222
B19: =B9 -> Machinery & Equipment | C19: 3.899559 | D19: 4.444885 | E19: 17.040662 | F19: 39.482876 | G19: 73.272624 | H19: =H28*'Financial Statements'!I$4 -> 46.454283 | I19: =I28*'Financial Statements'!J$4 -> 50.925764 | J19: =J28*'Financial Statements'!K$4 -> 54.47445 | K19: =K28*'Financial Statements'!L$4 -> 57.652889 | L19: =L28*'Financial Statements'!M$4 -> 60.891708
B20: =B10 -> Furniture & Fixtures | C20: 0.07145 | D20: 0.055793 | E20: 1.483433 | F20: 2.812388 | G20: 2.050673 | H20: =H29*'Financial Statements'!I$4 -> 2.2781633 | I20: =I29*'Financial Statements'!J$4 -> 2.4974491 | J20: =J29*'Financial Statements'!K$4 -> 2.6714801 | K20: =K29*'Financial Statements'!L$4 -> 2.8273539 | L20: =L29*'Financial Statements'!M$4 -> 2.9861887
B21: =B11 -> Other Installations | C21: 0.253335 | D21: 0.629997 | E21: 1.130954 | F21: 10.614696 | G21: 7.33789 | H21: =H30*'Financial Statements'!I$4 -> 6.57025 | I21: =I30*'Financial Statements'!J$4 -> 7.2026728 | J21: =J30*'Financial Statements'!K$4 -> 7.7045804 | K21: =K30*'Financial Statements'!L$4 -> 8.1541221 | L21: =L30*'Financial Statements'!M$4 -> 8.6122037
B22: =B12 -> Computers & Software | C22: 0.683167 | D22: 1.154801 | E22: 4.576678 | F22: 2.088324 | G22: 6.952454 | H22: =H31*'Financial Statements'!I$4 -> 6.129494 | I22: =I31*'Financial Statements'!J$4 -> 6.7194916 | J22: =J31*'Financial Statements'!K$4 -> 7.1877295 | K22: =K31*'Financial Statements'!L$4 -> 7.6071143 | L22: =L31*'Financial Statements'!M$4 -> 8.0344661
B23: =B13 -> Total | C23: =SUM(C16:C22) -> 32.443963 | D23: =SUM(D16:D22) -> 27.374376 | E23: =SUM(E16:E22) -> 56.808221 | F23: =SUM(F16:F22) -> 206.54263 | G23: =SUM(G16:G22) -> 329.8932 | H23: =SUM(H16:H22) -> 231.69836 | I23: =SUM(I16:I22) -> 254.0006 | J23: =SUM(J16:J22) -> 271.70026 | ... L23: =SUM(L16:L22) -> 303.70738
B25: =B16 -> Freehold Land | C25: =IFERROR(C16/'Financial Statements'!D$4,0) -> 0 | D25: =IFERROR(D16/'Financial Statements'!E$4,0) -> 0 | E25: =IFERROR(E16/'Financial Statements'!F$4,0) -> 0 | F25: =IFERROR(F16/'Financial Statements'!G$4,0) -> 0 | G25: =IFERROR(G16/'Financial Statements'!H$4,0) -> 0 | H25: =G25 -> 0 | I25: =H25 -> 0 | J25: =I25 -> 0 | K25: =J25 -> 0 | L25: =K25 -> 0
B26: =B17 -> Buildings | C26: =IFERROR(C17/'Financial Statements'!D$4,0) -> 0.010497545 | D26: =IFERROR(D17/'Financial Statements'!E$4,0) -> 0.0016228792 | E26: =IFERROR(E17/'Financial Statements'!F$4,0) -> 0.0042191477 | F26: =IFERROR(F17/'Financial Statements'!G$4,0) -> 0.0042134409 | G26: =IFERROR(G17/'Financial Statements'!H$4,0) -> 0.014653804 | H26: =AVERAGE(C26:G26) -> 0.0070413636 | I26: =H26 -> 0.0070413636 | J26: =I26 -> 0.0070413636 | K26: =J26 -> 0.0070413636 | L26: =K26 -> 0.0070413636
B27: =B18 -> Vehicles | C27: =IFERROR(C18/'Financial Statements'!D$4,0) -> 0.00074810485 | D27: =IFERROR(D18/'Financial Statements'!E$4,0) -> 0.0028881127 | E27: =IFERROR(E18/'Financial Statements'!F$4,0) -> 0.0011717845 | F27: =IFERROR(F18/'Financial Statements'!G$4,0) -> 0.013146023 | G27: =IFERROR(G18/'Financial Statements'!H$4,0) -> 0.0046499138 | H27: =AVERAGE(C27:G27) -> 0.0045207877 | I27: =H27 -> 0.0045207877 | J27: =I27 -> 0.0045207877 | K27: =J27 -> 0.0045207877 | L27: =K27 -> 0.0045207877
B28: =B19 -> Machinery & Equipment | C28: =IFERROR(C19/'Financial Statements'!D$4,0) -> 0.0015925464 | D28: =IFERROR(D19/'Financial Statements'!E$4,0) -> 0.00095077697 | E28: =IFERROR(E19/'Financial Statements'!F$4,0) -> 0.0028199797 | F28: =IFERROR(F19/'Financial Statements'!G$4,0) -> 0.0045227787 | G28: =IFERROR(G19/'Financial Statements'!H$4,0) -> 0.0058866184 | H28: =AVERAGE(C28:G28) -> 0.0031545401 | I28: =H28 -> 0.0031545401 | J28: =I28 -> 0.0031545401 | K28: =J28 -> 0.0031545401 | L28: =K28 -> 0.0031545401
B29: =B20 -> Furniture & Fixtures | C29: =IFERROR(C20/'Financial Statements'!D$4,0) -> 2.9179566e-05 | D29: =IFERROR(D20/'Financial Statements'!E$4,0) -> 1.1934324e-05 | E29: =IFERROR(E20/'Financial Statements'!F$4,0) -> 0.00024548641 | F29: =IFERROR(F20/'Financial Statements'!G$4,0) -> 0.00032216013 | G29: =IFERROR(G20/'Financial Statements'!H$4,0) -> 0.00016474815 | H29: =AVERAGE(C29:G29) -> 0.00015470172 | I29: =H29 -> 0.00015470172 | J29: =I29 -> 0.00015470172 | K29: =J29 -> 0.00015470172 | L29: =K29 -> 0.00015470172
B30: =B21 -> Other Installations | C30: =IFERROR(C21/'Financial Statements'!D$4,0) -> 0.00010345984 | D30: =IFERROR(D21/'Financial Statements'!E$4,0) -> 0.00013475864 | E30: =IFERROR(E21/'Financial Statements'!F$4,0) -> 0.00018715631 | F30: =IFERROR(F21/'Financial Statements'!G$4,0) -> 0.0012159175 | G30: =IFERROR(G21/'Financial Statements'!H$4,0) -> 0.00058951565 | H30: =AVERAGE(C30:G30) -> 0.00044616159 | I30: =H30 -> 0.00044616159 | J30: =I30 -> 0.00044616159 | K30: =J30 -> 0.00044616159 | L30: =K30 -> 0.00044616159
B31: =B22 -> Computers & Software | C31: =IFERROR(C22/'Financial Statements'!D$4,0) -> 0.00027899953 | D31: =IFERROR(D22/'Financial Statements'!E$4,0) -> 0.00024701611 | E31: =IFERROR(E22/'Financial Statements'!F$4,0) -> 0.00075737312 | F31: =IFERROR(F22/'Financial Statements'!G$4,0) -> 0.00023921832 | G31: =IFERROR(G22/'Financial Statements'!H$4,0) -> 0.00055855027 | H31: =AVERAGE(C31:G31) -> 0.00041623147 | I31: =H31 -> 0.00041623147 | J31: =I31 -> 0.00041623147 | K31: =J31 -> 0.00041623147 | L31: =K31 -> 0.00041623147
B33: Transferred from assets under construction
B34: =B16 -> Freehold Land | C34: 0 | D34: 0 | E34: 0 | F34: 0 | G34: 0
B35: =B17 -> Buildings | C35: 0 | D35: 0 | E35: 0 | F35: 0 | G35: 0
B36: =B18 -> Vehicles | C36: 0 | D36: 0 | E36: 0 | F36: 0 | G36: 0
B37: =B19 -> Machinery & Equipment | C37: 3.427052 | D37: 0 | E37: 0 | F37: 0 | G37: 781.88944 | H37: =G128 -> 391.54375
B38: =B20 -> Furniture & Fixtures | C38: 0 | D38: 0 | E38: 0 | F38: 0 | G38: 0
B39: =B21 -> Other Installations | C39: 0 | D39: 0 | E39: 3.261312 | F39: 1.0437 | G39: 0
B40: =B22 -> Computers & Software | C40: 0 | D40: 0 | E40: 0 | F40: 0 | G40: 0
B41: =B23 -> Total | C41: =SUM(C34:C40) -> 3.427052 | D41: =SUM(D34:D40) -> 0 | E41: =SUM(E34:E40) -> 3.261312 | F41: =SUM(F34:F40) -> 1.0437 | G41: =SUM(G34:G40) -> 781.88944 | H41: =SUM(H34:H40) -> 391.54375 | I41: =SUM(I34:I40) -> 0 | J41: =SUM(J34:J40) -> 0 | ... L41: =SUM(L34:L40) -> 0
B43: Disposals
B44: =B34 -> Freehold Land | C44: 0 | D44: 0 | E44: 0 | F44: 0 | G44: 0
B45: =B35 -> Buildings | C45: 0 | D45: 0 | E45: 0 | F45: 0 | G45: 0
...

Sheet Debt
B2: Footnotes BD | C2: 2021 | D2: =C2+1 -> 2022 | E2: =D2+1 -> 2023 | F2: =E2+1 -> 2024 | G2: =F2+1 -> 2025 | H2: =G2+1 -> 2026 | I2: =H2+1 -> 2027 | J2: =I2+1 -> 2028 | K2: =J2+1 -> 2029 | L2: =K2+1 -> 2030
B4: Borrowings
B5: Current
B6: Bank Loans - CIB | C6: 45.9 | D6: 56.1 | E6: 0 | F6: 0 | G6: 0 | H6: =G6 -> 0 | I6: =H6 -> 0 | J6: =I6 -> 0 | K6: =J6 -> 0 | L6: =K6 -> 0
B7: Bank Loans - NBE | C7: 0 | D7: 0 | E7: 0 | F7: 25.481075 | G7: 27.056585 | H7: =H27 -> 27.056585 | I7: =I27 -> 27.056585 | J7: =J27 -> 27.056585 | K7: =K27 -> 27.056585 | L7: =L27 -> 10.458559
B8: Bank Loans - EBRD | C8: 68.434781 | D8: 107.43478 | E8: 0 | F8: 0 | G8: 118.43656 | H8: =H35 -> 236.87312 | I8: =I35 -> 236.87312 | J8: =J35 -> 236.87312 | K8: =K35 -> 177.65484 | L8: =L35 -> 0
B9: Total Current Borrowings | C9: =SUM(C6:C8) -> 114.33478 | D9: =SUM(D6:D8) -> 163.53478 | E9: =SUM(E6:E8) -> 0 | F9: =SUM(F6:F8) -> 25.481075 | G9: =SUM(G6:G8) -> 145.49314 | H9: =SUM(H6:H8) -> 263.9297 | I9: =SUM(I6:I8) -> 263.9297 | J9: =SUM(J6:J8) -> 263.9297 | ... L9: =SUM(L6:L8) -> 10.458559
B10: Non-Current
B11: Bank Loans - CIB | C11: 153 | D11: 96.9 | E11: 0 | F11: 0 | G11: 0 | H11: =G11 -> 0 | I11: =H11 -> 0 | J11: =I11 -> 0 | K11: =J11 -> 0 | L11: =K11 -> 0
B12: Bank Loans - NBE | C12: 0 | D12: 0 | E12: 0 | F12: 120.39238 | G12: 118.6849 | H12: =H28 -> 91.628314 | I12: =I28 -> 64.571729 | J12: =J28 -> 37.515144 | K12: =K28 -> 10.458559 | L12: =L28 -> 0
B13: Bank Loans - EBRD | C13: 119.76091 | D13: 80.57609 | E13: 0 | F13: 0 | G13: 769.83764 | H13: =H36 -> 651.40108 | I13: =I36 -> 414.52796 | J13: =J36 -> 177.65484 | K13: =K36 -> 0 | L13: =L36 -> 0
B14: Total Non-Current Borrowings | C14: =SUM(C11:C13) -> 272.76091 | D14: =SUM(D11:D13) -> 177.47609 | E14: =SUM(E11:E13) -> 0 | F14: =SUM(F11:F13) -> 120.39238 | G14: =SUM(G11:G13) -> 888.52254 | H14: =SUM(H11:H13) -> 743.02939 | I14: =SUM(I11:I13) -> 479.09969 | J14: =SUM(J11:J13) -> 215.16998 | ... L14: =SUM(L11:L13) -> 0
B16: Long-Term Bank Loan Debt Schedule
B17: 6M EURIBOR Proxy | C17: 0.0282
A18: https://www.euribor-rates.eu/en/current-euribor-rates/ | B18: 3M EURIBOR Proxy | C18: 0.02647
B19: NBE All-in Rate | C19: =C17+0.03 -> 0.0582 | D19: (6M EURIBOR + 3.0% margin per KfW facility agreement)
B20: EBRD All-in Rate | C20: =C18+0.0435 -> 0.06997 | D20: (3M EURIBOR + 4.35% margin per EBRD facility agreement)
B22: NBE Loan | M22: Phase 3,20 equal quarterly instalments
B23: Beg. Balance | H23: =G7+G12 -> 145.74148 | I23: =H26 -> 118.6849 | J23: =I26 -> 91.628314 | K23: =J26 -> 64.571729 | L23: =K26 -> 37.515144
B24: Scheduled Repayment | H24: =MIN($G$7,H23) -> 27.056585 | I24: =MIN($G$7,I23) -> 27.056585 | J24: =MIN($G$7,J23) -> 27.056585 | K24: =MIN($G$7,K23) -> 27.056585 | L24: =MIN($G$7,L23) -> 27.056585 | M24: (assumed last actual annual instalment, held flat until repaid)
B25: Interest Expense | H25: =H23*$C$19 -> 8.4821544 | I25: =I23*$C$19 -> 6.9074611 | J25: =J23*$C$19 -> 5.3327679 | K25: =K23*$C$19 -> 3.7580746 | L25: =L23*$C$19 -> 2.1833814 | M25: (Beg. Balance x NBE rate)
B26: Ending Balance | H26: =H23-H24 -> 118.6849 | I26: =I23-I24 -> 91.628314 | J26: =J23-J24 -> 64.571729 | K26: =K23-K24 -> 37.515144 | L26: =L23-L24 -> 10.458559
B27: Current Portion (next 12 months due) | H27: =MIN($G$7,H26) -> 27.056585 | I27: =MIN($G$7,I26) -> 27.056585 | J27: =MIN($G$7,J26) -> 27.056585 | K27: =MIN($G$7,K26) -> 27.056585 | L27: =MIN($G$7,L26) -> 10.458559
B28: Non-Current Portion | H28: =H26-H27 -> 91.628314 | I28: =I26-I27 -> 64.571729 | J28: =J26-J27 -> 37.515144 | K28: =K26-K27 -> 10.458559 | L28: =L26-L27 -> 0
B30: EBRD Loan | M30: (15 equal quarterly instalments, first due ~18 months after FY2025 agreement date)
B31: Beg. Balance | H31: =G8+G13 -> 888.27419 | I31: =H34 -> 888.27419 | J31: =I34 -> 651.40108 | K31: =J34 -> 414.52796 | L31: =K34 -> 177.65484
B32: Scheduled Repayment | H32: 0 | I32: =MIN($H$31/15*4,I31) -> 236.87312 | J32: =MIN($H$31/15*4,J31) -> 236.87312 | K32: =MIN($H$31/15*4,K31) -> 236.87312 | L32: =L31 -> 177.65484 | M32: (18-month grace in 2026; ~4 instalments/yr from 2027; final payoff 2030)
B33: Interest Expense | H33: =H31*$C$20 -> 62.152545 | I33: =I31*$C$20 -> 62.152545 | J33: =J31*$C$20 -> 45.578533 | K33: =K31*$C$20 -> 29.004521 | L33: =L31*$C$20 -> 12.430509 | M33: (Beg. Balance x EBRD rate)
B34: Ending Balance | H34: =H31-H32 -> 888.27419 | I34: =I31-I32 -> 651.40108 | J34: =J31-J32 -> 414.52796 | K34: =K31-K32 -> 177.65484 | L34: =L31-L32 -> 0
B35: Current Portion (next 12 months due) | H35: =I32 -> 236.87312 | I35: =J32 -> 236.87312 | J35: =K32 -> 236.87312 | K35: =L32 -> 177.65484 | L35: 0
B36: Non-Current Portion | H36: =H34-H35 -> 651.40108 | I36: =I34-I35 -> 414.52796 | J36: =J34-J35 -> 177.65484 | K36: =K34-K35 -> 0 | L36: =L34-L35 -> 0
B39: Credit Facilities
B40: CF - CIB | C40: 240.38696 | D40: 162.16464 | E40: 73.528497 | F40: 615.04423 | G40: 99.916937
B41: CF -NBE | C41: 0 | D41: 198.47956 | E41: 16.545438 | F41: 0 | G41: 0
B42: CF - EG | C42: 0 | D42: 0 | E42: 0.000338 | F42: 0 | G42: 0
B43: Total | C43: =SUM(C40:C41) -> 240.38696 | D43: =SUM(D40:D42) -> 360.6442 | E43: =SUM(E40:E42) -> 90.074273 | F43: =SUM(F40:F42) -> 615.04423 | G43: =SUM(G40:G42) -> 99.916937 | H43: =H44*'Financial Statements'!I88 -> 134.16668 | I43: =I44*'Financial Statements'!J88 -> 146.39711 | J43: =J44*'Financial Statements'!K88 -> 156.78447 | K43: =K44*'Financial Statements'!L88 -> 166.0692 | L43: =L44*'Financial Statements'!M88 -> 175.52873
C44: =-C43/'Financial Statements'!D87 -> 0.63771635 | D44: =-D43/'Financial Statements'!E87 -> 0.76772231 | E44: =-E43/'Financial Statements'!F87 -> 0.48862668 | F44: =F43/'Financial Statements'!G87 -> 65.693977 | G44: =G43/'Financial Statements'!H88 -> 0.17290066 | H44: =G44 -> 0.17290066 | I44: =H44 -> 0.17290066 | J44: =I44 -> 0.17290066 | K44: =J44 -> 0.17290066 | L44: =K44 -> 0.17290066
B46: Deferred Tax Liabilities
B47: Beg. Balance | C47: 323.76501 | D47: =C49 -> 301.47283 | E47: =D49 -> 266.20171 | F47: =-E49 -> -282.21862 | G47: =F49 -> -241.14699
B48: Recognized in profit or loss from Dp of FA | C48: -22.29218 | D48: -35.271117 | E48: 16.016906 | F48: 41.071622 | G48: -14.169166
...

Sheet Revenue Bridge
B2: Revenue Bridge | C2: 2021 | D2: =C2+1 -> 2022 | E2: =D2+1 -> 2023 | F2: =E2+1 -> 2024 | G2: =F2+1 -> 2025 | H2: =G2+1 -> 2026 | I2: =H2+1 -> 2027 | J2: =I2+1 -> 2028 | K2: =J2+1 -> 2029 | L2: =K2+1 -> 2030
B4: Sales
B5: =IS!B5 -> Local
B6: =IS!B6 -> Sales | C6: =IS!C6 -> 2054.1196 | D6: =IS!D6 -> 3821.5448 | E6: =IS!E6 -> 3906.434 | F6: =IS!F6 -> 4703.4792 | G6: =IS!G6 -> 8350.4546 | H6: =H57*H70 -> 10320.725 | I6: =I57*I70 -> 10902.035 | J6: =J57*J70 -> 11738.811 | K6: =K57*K70 -> 12495.316 | L6: =L57*L70 -> 13301.991
B7: =IS!B7 -> Services | C7: =IS!C7 -> 92.559521 | D7: =IS!D7 -> 103.05889 | E7: =IS!E7 -> 82.820228 | F7: =IS!F7 -> 179.82523 | G7: =IS!G7 -> 281.86355 | H7: =Assumptions!J172*($G$7/($G$7+$G$11)) -> 290.31945 | I7: =Assumptions!K172*($G$7/($G$7+$G$11)) -> 299.02904 | J7: =Assumptions!L172*($G$7/($G$7+$G$11)) -> 307.99991 | K7: =Assumptions!M172*($G$7/($G$7+$G$11)) -> 317.2399 | L7: =Assumptions!N172*($G$7/($G$7+$G$11)) -> 326.7571
B8: =IS!B8 -> Total Local Sales | C8: =IS!C8 -> 2146.6791 | D8: =IS!D8 -> 3924.6037 | E8: =IS!E8 -> 3989.2543 | F8: =IS!F8 -> 4883.3045 | G8: =IS!G8 -> 8632.3182 | H8: =H6+H7 -> 10611.044 | I8: =I6+I7 -> 11201.064 | J8: =J6+J7 -> 12046.811 | K8: =K6+K7 -> 12812.556 | L8: =L6+L7 -> 13628.748
B9: =IS!B9 -> Export
B10: =IS!B10 -> Sales | C10: =IS!C10 -> 237.80973 | D10: =IS!D10 -> 667.51415 | E10: =IS!E10 -> 1622.381 | F10: =IS!F10 -> 3222.781 | G10: =IS!G10 -> 3356.4224 | H10: =H61*H72 -> 3642.7859 | I10: =I61*I72 -> 4456.0709 | J10: =J61*J72 -> 4720.6741 | K10: =K61*K72 -> 4947.472 | L10: =L61*L72 -> 5142.5129
B11: =IS!B11 -> Services | C11: =IS!C11 -> 64.142523 | D11: =IS!D11 -> 82.884935 | E11: =IS!E11 -> 431.19609 | F11: =IS!F11 -> 623.6973 | G11: =IS!G11 -> 458.57954 | H11: =Assumptions!J172*($G$11/($G$7+$G$11)) -> 472.33693 | I11: =Assumptions!K172*($G$11/($G$7+$G$11)) -> 486.50704 | J11: =Assumptions!L172*($G$11/($G$7+$G$11)) -> 501.10225 | K11: =Assumptions!M172*($G$11/($G$7+$G$11)) -> 516.13532 | L11: =Assumptions!N172*($G$11/($G$7+$G$11)) -> 531.61938
B12: =IS!B12 -> Total Export Sales | C12: =IS!C12 -> 301.95225 | D12: =IS!D12 -> 750.39909 | E12: =IS!E12 -> 2053.5771 | F12: =IS!F12 -> 3846.4783 | G12: =IS!G12 -> 3815.0019 | H12: =H10+H11 -> 4115.1228 | I12: =I10+I11 -> 4942.5779 | J12: =J10+J11 -> 5221.7763 | K12: =K10+K11 -> 5463.6073 | L12: =L10+L11 -> 5674.1322
B13: =B10 -> Sales | C13: =C6+C10 -> 2291.9293 | D13: =D6+D10 -> 4489.059 | E13: =E6+E10 -> 5528.815 | F13: =F6+F10 -> 7926.2603 | G13: =G6+G10 -> 11706.877 | H13: =H6+H10 -> 13963.51 | I13: =I6+I10 -> 15358.105 | J13: =J6+J10 -> 16459.485 | ... L13: =L6+L10 -> 18444.503
B14: =B11 -> Services | C14: =C7+C11 -> 156.70204 | D14: =D7+D11 -> 185.94382 | E14: =E7+E11 -> 514.01632 | F14: =F7+F11 -> 803.52253 | G14: =G7+G11 -> 740.44309 | H14: =H7+H11 -> 762.65638 | I14: =I7+I11 -> 785.53607 | J14: =J7+J11 -> 809.10216 | ... L14: =L7+L11 -> 858.37648
B15: =IS!B13 -> Total Revenue | C15: =SUM(C13:C14) -> 2448.6314 | D15: =SUM(D13:D14) -> 4675.0028 | E15: =SUM(E13:E14) -> 6042.8313 | F15: =SUM(F13:F14) -> 8729.7828 | G15: =SUM(G13:G14) -> 12447.32 | H15: =SUM(H13:H14) -> 14726.167 | I15: =SUM(I13:I14) -> 16143.641 | J15: =SUM(J13:J14) -> 17268.587 | ... L15: =SUM(L13:L14) -> 19302.88
B17: Sales %
B18: =B5 -> Local
B19: =B6 -> Sales | C19: =C6/$C$15 -> 0.83888478 | D19: =D6/$D$15 -> 0.81744225 | E19: =E6/$E$15 -> 0.64645757 | F19: =F6/$F$15 -> 0.53878537 | G19: =G6/$G$15 -> 0.67086365 | H19: =H6/$H$15 -> 0.70084257 | I19: =I6/$G$15 -> 0.87585396 | J19: =J6/$G$15 -> 0.94307939 | K19: =K6/$G$15 -> 1.0038559 | L19: =L6/$G$15 -> 1.068663
B20: =B7 -> Services | C20: =C7/$C$15 -> 0.037800513 | D20: =D7/$D$15 -> 0.022044669 | E20: =E7/$E$15 -> 0.013705534 | F20: =F7/$F$15 -> 0.02059905 | G20: =G7/$G$15 -> 0.022644517 | H20: =AVERAGE(C20:G20) -> 0.023358856 | I20: =AVERAGE(D20:H20) -> 0.020470525 | J20: =AVERAGE(E20:I20) -> 0.020155696 | K20: =AVERAGE(F20:J20) -> 0.021445729 | L20: =AVERAGE(G20:K20) -> 0.021615065
B21: =B8 -> Total Local Sales | C21: =C8/$C$15 -> 0.8766853 | D21: =D8/$D$15 -> 0.83948692 | E21: =E8/$E$15 -> 0.6601631 | F21: =F8/$F$15 -> 0.55938442 | G21: =G8/$G$15 -> 0.69350817 | H21: =H8/$G$15 -> 0.85247619 | I21: =I8/$G$15 -> 0.89987752 | J21: =J8/$G$15 -> 0.96782367 | K21: =K8/$G$15 -> 1.0293425 | L21: =L8/$G$15 -> 1.0949142
B22: =B9 -> Export
B23: =B10 -> Sales | C23: =C10/$C$15 -> 0.097119448 | D23: =D10/$D$15 -> 0.14278369 | E23: =E10/$E$15 -> 0.26848027 | F23: =F10/$F$15 -> 0.36917082 | G23: =G10/$G$15 -> 0.2696502 | H23: =H10/$G$15 -> 0.29265624 | I23: =I10/$G$15 -> 0.3579944 | J23: =J10/$G$15 -> 0.37925224 | K23: =K10/$G$15 -> 0.39747287 | L23: =L10/$G$15 -> 0.41314217
B24: =B11 -> Services | C24: =C11/$C$15 -> 0.026195255 | D24: =D11/$D$15 -> 0.017729387 | E24: =E11/$E$15 -> 0.071356631 | F24: =F11/$F$15 -> 0.071444767 | G24: =G11/$G$15 -> 0.036841629 | H24: =AVERAGE(C24:G24) -> 0.044713534 | I24: =H24 -> 0.044713534 | J24: =I24 -> 0.044713534 | K24: =J24 -> 0.044713534 | L24: =K24 -> 0.044713534
B25: =B12 -> Total Export Sales | C25: =C12/$C$15 -> 0.1233147 | D25: =D12/$D$15 -> 0.16051308 | E25: =E12/$E$15 -> 0.3398369 | F25: =F12/$F$15 -> 0.44061558 | G25: =G12/$G$15 -> 0.30649183 | H25: =H12/$G$15 -> 0.33060312 | I25: =I12/$G$15 -> 0.39707968 | J25: =J12/$G$15 -> 0.41951009 | K25: =K12/$G$15 -> 0.43893844 | L25: =L12/$G$15 -> 0.45585172
B26: =B15 -> Total Revenue | C26: =C15/C$15 -> 1 | D26: =D15/D$15 -> 1 | E26: =E15/E$15 -> 1 | F26: =F15/F$15 -> 1 | G26: =G15/G$15 -> 1 | H26: =H15/H$15 -> 1 | I26: =I15/I$15 -> 1 | J26: =J15/J$15 -> 1 | ... L26: =L15/L$15 -> 1
B27: Local | C27: =C6/C13 -> 0.89624037 | D27: =D6/D13 -> 0.85130199 | E27: =E6/E13 -> 0.70655901 | F27: =F6/F13 -> 0.59340459 | G27: =G6/G13 -> 0.71329481 | H27: =H6/H13 -> 0.73912105 | I27: =I6/I13 -> 0.70985543 | J27: =J6/J13 -> 0.7131943 | ... L27: =L6/L13 -> 0.72118995
B28: Export | C28: =C10/C13 -> 0.10375963 | D28: =D10/D13 -> 0.14869801 | E28: =E10/E13 -> 0.29344099 | F28: =F10/F13 -> 0.40659541 | G28: =G10/G13 -> 0.28670519 | H28: =H10/H13 -> 0.26087895 | I28: =I10/I13 -> 0.29014457 | J28: =J10/J13 -> 0.2868057 | ... L28: =L10/L13 -> 0.27881005
B30: Production Volume
B31: Clinker | C31: 3.19 | D31: 3.81 | E31: 3.93 | F31: 3.61 | G31: 3.8516 | H31: =G31*(1+Assumptions!J137) -> 3.928632 | I31: =H31*(1+Assumptions!K137) -> 4.0072046 | J31: =I31*(1+Assumptions!L137) -> 4.0873487 | K31: =J31*(1+Assumptions!M137) -> 4.1690957 | L31: =K31*(1+0.5%) -> 4.1899412
B32: Cement | C32: 2.8 | D32: 3.25 | E32: 2.76 | F32: 2.94 | G32: 3.4806 | H32: =G32*(1+Assumptions!J70) -> 3.65463 | I32: =H32*(1+Assumptions!K70) -> 3.8299491 | J32: =I32*(1+Assumptions!L70) -> 4.0062415 | K32: =J32*(1+Assumptions!M70) -> 4.1859895 | L32: =K32*(1+Assumptions!N70) -> 4.366083
B33: Total | C33: =SUM(C31:C32) -> 5.99 | D33: =SUM(D31:D32) -> 7.06 | E33: =SUM(E31:E32) -> 6.69 | F33: =SUM(F31:F32) -> 6.55 | G33: =SUM(G31:G32) -> 7.3322 | H33: =SUM(H31:H32) -> 7.583262 | I33: =SUM(I31:I32) -> 7.8371538 | J33: =SUM(J31:J32) -> 8.0935902 | ... L33: =SUM(L31:L32) -> 8.5560241
B35: Capacity & Utilization
B36: Clinker Capacity | C36: 4.2 | D36: 4.2 | E36: 4.2 | F36: 4.2 | G36: 4.2 | H36: 4.2 | I36: 4.2 | J36: 4.2 | K36: 4.2 | L36: 4.2
B37: Cement Capacity | C37: 5 | D37: 5 | E37: 5 | F37: 5 | G37: 5 | H37: 5 | I37: 5 | J37: 5 | K37: 5 | L37: 5
B38: Clinker Utilization | C38: =C31/C36 -> 0.75952381 | D38: =D31/D36 -> 0.90714286 | E38: =E31/E36 -> 0.93571429 | F38: =F31/F36 -> 0.85952381 | G38: =G31/G36 -> 0.91704762 | H38: =H31/H36 -> 0.93538857 | I38: =I31/I36 -> 0.95409634 | J38: =J31/J36 -> 0.97317827 | ... L38: =L31/L36 -> 0.99760504
B39: Cement Utilization | C39: =C32/C37 -> 0.56 | D39: =D32/D37 -> 0.65 | E39: =E32/E37 -> 0.552 | F39: =F32/F37 -> 0.588 | G39: =G32/G37 -> 0.69612 | H39: =H32/H37 -> 0.730926 | I39: =I32/I37 -> 0.76598982 | J39: =J32/J37 -> 0.8012483 | ... L39: =L32/L37 -> 0.87321659
B40: Total Utilization | C40: =C33/C37 -> 1.198 | D40: =D33/D37 -> 1.412 | E40: =E33/E37 -> 1.338 | F40: =F33/F37 -> 1.31 | G40: =G33/G37 -> 1.46644 | H40: =H33/H37 -> 1.5166524 | I40: =I33/I37 -> 1.5674308 | J40: =J33/J37 -> 1.618718 | ... L40: =L33/L37 -> 1.7112048
B42: Volume
B43: Clinker Local | C43: 0.091 | D43: 0.341 | E43: 0.08 | F43: 0 | G43: 0.6116162 | H43: =H49*H45 -> 0.55533214 | I43: =I49*I45 -> 0.54556592 | J43: =J49*J45 -> 0.53654434 | K43: =K49*K45 -> 0.52799062 | L43: =L49*L45 -> 0.51494023 | N43: % | O43: 2025 | P43: 2030
B44: Clinker Export | C44: 0.325 | D44: 0.936 | E44: 1.5419 | F44: 2.0744 | G44: 1.3005 | H44: =H50*H45 -> 1.1808213 | I44: =I50*I45 -> 1.1600551 | J44: =J50*J45 -> 1.1408722 | K44: =K50*K45 -> 1.1226841 | L44: =L50*L45 -> 1.0949346 | N44: Volume
B45: Total Clinker | C45: =SUM(C43:C44) -> 0.416 | D45: =SUM(D43:D44) -> 1.277 | E45: =SUM(E43:E44) -> 1.6219 | F45: =SUM(F43:F44) -> 2.0744 | G45: =SUM(G43:G44) -> 1.9121162 | H45: =H65*H31 -> 1.7361535 | I45: =I65*I31 -> 1.705621 | J45: =J65*J31 -> 1.6774165 | K45: =K65*K31 -> 1.6506748 | L45: =L65*L31 -> 1.6098749 | M45: =_xlfn.RRI(4,C45,G45) -> 0.4642163 | N45: Local | O45: =G57/G62 -> 0.60235701 | P45: =L57/L62 -> 0.72118995
B46: Cement Local | C46: 2.62 | D46: 3.218 | E46: 2.595 | F46: 2.6183 | G46: 2.86244 | H46: =H51*H48 -> 2.9758727 | I46: =I51*I48 -> 3.0037112 | J46: =J51*J48 -> 3.0294272 | K46: =K51*K48 -> 3.0538095 | L46: =L51*L48 -> 3.0910095 | N46: Export | O46: =G61/G62 -> 0.39764299 | P46: =L61/L62 -> 0.27881005
...

Sheet COGS Bridge
B2: COGS Bridge | C2: Unit | D2: 2021 | E2: =D2+1 -> 2022 | F2: =E2+1 -> 2023 | G2: =F2+1 -> 2024 | H2: =G2+1 -> 2025 | I2: =H2+1 -> 2026 | J2: =I2+1 -> 2027 | K2: =J2+1 -> 2028 | L2: =K2+1 -> 2029 | M2: =L2+1 -> 2030
B4: Cost of Sales
B5: Raw materials | C5: Mn EGP | D5: 1705.51 | E5: 3118.7494 | F5: 3779.8177 | G5: 5225.344 | H5: 5698.1847 | I5: =IF('Financial Statements'!$N$1="Core",(Assumptions!J165+Assumptions!J166)*'Revenue Bridge'!H62,'ESG Integration'!I67*Assumptions!J176) -> 6474.3241 | J5: =IF('Financial Statements'!$N$1="Core",(Assumptions!K165+Assumptions!K166)*'Revenue Bridge'!I62,'ESG Integration'!J67*Assumptions!K176) -> 7008.5278 | K5: =IF('Financial Statements'!$N$1="Core",(Assumptions!L165+Assumptions!L166)*'Revenue Bridge'!J62,'ESG Integration'!K67*Assumptions!L176) -> 7494.7175 | L5: =IF('Financial Statements'!$N$1="Core",(Assumptions!M165+Assumptions!M166)*'Revenue Bridge'!K62,'ESG Integration'!L67*Assumptions!M176) -> 7938.1413 | M5: =IF('Financial Statements'!$N$1="Core",(Assumptions!N165+Assumptions!N166)*'Revenue Bridge'!L62,'ESG Integration'!M67*Assumptions!N176) -> 8400.9751
B6: Depreciation | C6: Mn EGP | D6: 215.82438 | E6: 205.95811 | F6: 212.76065 | G6: 217.7172 | H6: 254.76555
B7: Amortization of Licenses, Intangible assets | C7: Mn EGP | D7: 34.624973 | E7: 28.156249 | F7: 28.156249 | G7: 28.156249 | H7: 28.156249
B8: Amortization of right of use | C8: Mn EGP | D8: 5.902848 | E8: 5.487561 | F8: 6.891333 | G8: 7.082414 | H8: 2.525364
B9: Transportation costs | C9: Mn EGP | D9: 114.65141 | E9: 165.49009 | F9: 498.18933 | G9: 792.24221 | H9: 764.27933 | I9: =H9*(1+Assumptions!J8) -> 865.1642 | J9: =I9*(1+Assumptions!K8) -> 961.19743 | K9: =J9*(1+Assumptions!L8) -> 1039.0544 | L9: =K9*(1+Assumptions!M8) -> 1103.4758 | M9: =L9*(1+Assumptions!N8) -> 1163.0635
B10: Overhead costs | C10: Mn EGP | D10: 204.57001 | E10: 265.97482 | F10: 233.99995 | G10: 372.4304 | H10: 641.14321 | I10: =H10*(1+Assumptions!J8) -> 725.77411 | J10: =I10*(1+Assumptions!K8) -> 806.33504 | K10: =J10*(1+Assumptions!L8) -> 871.64818 | L10: =K10*(1+Assumptions!M8) -> 925.69036 | M10: =L10*(1+Assumptions!N8) -> 975.67764
B11: Total | C11: Mn EGP | D11: =SUM(D5:D10) -> 2281.0836 | E11: =SUM(E5:E10) -> 3789.8162 | F11: =SUM(F5:F10) -> 4759.8152 | G11: =SUM(G5:G10) -> 6642.9725 | H11: =SUM(H5:H10) -> 7389.0544 | I11: =SUM(I5:I10) -> 8065.2624 | J11: =SUM(J5:J10) -> 8776.0602 | K11: =SUM(K5:K10) -> 9405.4201 | ... M11: =SUM(M5:M10) -> 10539.716
B13: COGS %
B14: =B5 -> Raw materials | C14: % | D14: =D5/$D$11 -> 0.74767535 | E14: =E5/$E$11 -> 0.82292893 | F14: =F5/$F$11 -> 0.79411018 | G14: =G5/$G$11 -> 0.78659727 | H14: =H5/$H$11 -> 0.77116562 | I14: =I5/$I$11 -> 0.8027419 | J14: =J5/$J$11 -> 0.79859613 | K14: =K5/$K$11 -> 0.7968509 | L14: =L5/$L$11 -> 0.79641782 | M14: =M5/$M$11 -> 0.79707792
B15: =B6 -> Depreciation | C15: % | D15: =D6/$D$11 -> 0.094614851 | E15: =E6/$E$11 -> 0.054345144 | F15: =F6/$F$11 -> 0.044699351 | G15: =G6/$G$11 -> 0.032774064 | H15: =H6/$H$11 -> 0.034478775
B16: =B7 -> Amortization of Licenses, Intangible assets | C16: % | D16: =D7/$D$11 -> 0.015179178 | E16: =E7/$E$11 -> 0.0074294497 | F16: =F7/$F$11 -> 0.005915408 | G16: =G7/$G$11 -> 0.0042385015 | H16: =H7/$H$11 -> 0.0038105348
B17: =B8 -> Amortization of right of use | C17: % | D17: =D8/$D$11 -> 0.0025877386 | E17: =E8/$E$11 -> 0.0014479755 | F17: =F8/$F$11 -> 0.0014478152 | G17: =G8/$G$11 -> 0.0010661513 | H17: =H8/$H$11 -> 0.00034177093
B18: =B9 -> Transportation costs | C18: % | D18: =D9/$D$11 -> 0.050261817 | E18: =E9/$E$11 -> 0.043667049 | F18: =F9/$F$11 -> 0.10466569 | G18: =G9/$G$11 -> 0.1192602 | H18: =H9/$H$11 -> 0.10343398 | I18: =I9/$I$11 -> 0.10727043 | J18: =J9/$J$11 -> 0.10952494 | K18: =K9/$K$11 -> 0.110474 | L18: =L9/$L$11 -> 0.11070952 | M18: =M9/$M$11 -> 0.11035055
B19: =B10 -> Overhead costs | C19: % | D19: =D10/$D$11 -> 0.089681065 | E19: =E10/$E$11 -> 0.070181456 | F19: =F10/$F$11 -> 0.049161561 | G19: =G10/$G$11 -> 0.056063817 | H19: =H10/$H$11 -> 0.086769317 | I19: =I10/$I$11 -> 0.089987662 | J19: =J10/$J$11 -> 0.091878932 | K19: =K10/$K$11 -> 0.092675093 | L19: =L10/$L$11 -> 0.092872661 | M19: =M10/$M$11 -> 0.092571528
B20: =B11 -> Total | C20: % | D20: =SUM(D14:D19) -> 1 | E20: =SUM(E14:E19) -> 1 | F20: =SUM(F14:F19) -> 1 | G20: =SUM(G14:G19) -> 1 | H20: =SUM(H14:H19) -> 1
B22: COGS /Ton
B23: Clinker Production | C23: Mn ton | D23: 3.189 | E23: 3.9164 | F23: 3.9271 | G23: 3.6067 | H23: 3.8516
B24: Cement Production | C24: Mn ton | D24: 2.796 | E24: 3.2536 | F24: 2.7626 | G24: 2.9354 | H24: 3.4806
B25: Production Volume | C25: Mn ton | D25: =D23+D24 -> 5.985 | E25: =E23+E24 -> 7.17 | F25: =F23+F24 -> 6.6897 | G25: =G23+G24 -> 6.5421 | H25: =H23+H24 -> 7.3322 | I25: ='Revenue Bridge'!H33 -> 7.583262 | J25: ='Revenue Bridge'!I33 -> 7.8371538 | K25: ='Revenue Bridge'!J33 -> 8.0935902 | L25: ='Revenue Bridge'!K33 -> 8.3550852 | M25: ='Revenue Bridge'!L33 -> 8.5560241
B26: RM/ton | D26: =D5/'Revenue Bridge'!C62 -> 531.64276 | E26: =E5/'Revenue Bridge'!D62 -> 683.80131 | F26: =F5/'Revenue Bridge'!E62 -> 863.72143 | G26: =G5/'Revenue Bridge'!F62 -> 1033.8208 | H26: =H5/'Revenue Bridge'!G62 -> 1174.012 | I26: =Assumptions!J165+Assumptions!J166 -> 1294.8648 | J26: =Assumptions!K165+Assumptions!K166 -> 1401.7056 | K26: =Assumptions!L165+Assumptions!L166 -> 1498.9435 | L26: =Assumptions!M165+Assumptions!M166 -> 1587.6283 | M26: =Assumptions!N165+Assumptions!N166 -> 1680.195
B27: Transportation/ton | D27: =D9/'Revenue Bridge'!C62 -> 35.739216 | E27: =E9/'Revenue Bridge'!D62 -> 36.284525 | F27: =F9/'Revenue Bridge'!E62 -> 113.84062 | G27: =G9/'Revenue Bridge'!F62 -> 156.74308 | H27: =H9/'Revenue Bridge'!G62 -> 157.46649 | I27: =I9/I25 -> 114.08866 | J27: =J9/J25 -> 122.64624 | K27: =K9/K25 -> 128.37991 | L27: =L9/L25 -> 132.07236 | M27: =M9/M25 -> 135.93504
B28: Overhead/ton | D28: =D10/'Revenue Bridge'!C62 -> 63.768705 | E28: =E10/'Revenue Bridge'!D62 -> 58.316302 | F28: =F10/'Revenue Bridge'!E62 -> 53.471036 | G28: =G10/'Revenue Bridge'!F62 -> 73.684393 | H28: =H10/'Revenue Bridge'!G62 -> 132.09642 | I28: =I10/I25 -> 95.707377 | J28: =J10/J25 -> 102.88621 | K28: =K10/K25 -> 107.69611 | L28: =L10/L25 -> 110.79365 | M28: =M10/M25 -> 114.034
B29: COGS/ton | D29: =D11/'Revenue Bridge'!C62 -> 711.06097 | E29: =E11/'Revenue Bridge'!D62 -> 830.93605 | F29: =F11/'Revenue Bridge'!E62 -> 1087.6594 | G29: =G11/'Revenue Bridge'!F62 -> 1314.295 | H29: =H11/'Revenue Bridge'!G62 -> 1522.3864 | I29: =I11/'Revenue Bridge'!H62 -> 1613.0525 | J29: =J11/'Revenue Bridge'!I62 -> 1755.212 | K29: =K11/'Revenue Bridge'!J62 -> 1881.084 | ... M29: =M11/'Revenue Bridge'!L62 -> 2107.9433
B32: Effects
B33: Volume Effect | E33: =(E25-D25)*D29 -> 842.60725 | F33: =(F25-E25)*E29 -> -399.09858 | G33: =(G25-F25)*F29 -> -160.53853 | H33: =(H25-G25)*G29 -> 1038.4245 | I33: =(I25-H25)*H29 -> 382.21336 | J33: =(J25-I25)*I29 -> 409.54072 | K33: =(K25-J25)*J29 -> 450.1004 | L33: =(L25-K25)*K29 -> 491.89392 | M33: =(M25-L25)*L29 -> 400.56412
B34: COGS /Ton Effect | E34: =(E11-D11)-E33 -> 666.12538 | F34: =(F11-E11)-F33 -> 1369.0976 | G34: =(G11-F11)-G33 -> 2043.6958 | H34: =(H11-G11)-H33 -> -292.34253 | I34: =(I11-H11)-I33 -> 293.99467 | J34: =(J11-I11)-J33 -> 301.25706 | K34: =(K11-J11)-K33 -> 179.25944 | L34: =(L11-K11)-L33 -> 69.993435 | M34: =(M11-L11)-M33 -> 171.84473
B35: Total COGS Change | E35: =E33+E34 -> 1508.7326 | F35: =F33+F34 -> 969.999 | G35: =G33+G34 -> 1883.1573 | H35: =H33+H34 -> 746.08193 | I35: =I33+I34 -> 676.20803 | J35: =J33+J34 -> 710.79778 | K35: =K33+K34 -> 629.35984 | L35: =L33+L34 -> 561.88736 | M35: =M33+M34 -> 572.40886
B37: Inflation Impact
B38: COGS/ton growth | C38: % | E38: =E29/D29-1 -> 0.16858622 | F38: =F29/E29-1 -> 0.30895686 | G38: =G29/F29-1 -> 0.20836994 | H38: =H29/G29-1 -> 0.15832929
B39: Inflation | C39: % | E39: =Assumptions!F8 -> 0.132 | F39: =Assumptions!G8 -> 0.357 | G39: =Assumptions!H8 -> 0.275 | H39: =Assumptions!I8 -> 0.149
B40: Difference | E40: =E38-E39 -> 0.036586216 | F40: =F38-F39 -> -0.048043145 | G40: =G38-G39 -> -0.066630056 | H40: =H38-H39 -> 0.0093292888
B43: FX Sensitivity
B44: EX rate | C44: USD/EGP | D44: =Assumptions!E6 -> 15.66 | E44: =Assumptions!F6 -> 24.69 | F44: =Assumptions!G6 -> 30.84 | G44: =Assumptions!H6 -> 50.79 | H44: =Assumptions!I6 -> 47.09
B45: YoY depreciation | E45: =E44/D44-1 -> 0.57662835 | F45: =F44/E44-1 -> 0.2490887 | G45: =G44/F44-1 -> 0.64688716 | H45: =H44/G44-1 -> -0.072848986
B46: Coal Cost | C46: =Assumptions!D141 -> USD/ton | D46: =Assumptions!E141 -> 183.88 | E46: =Assumptions!F141 -> 370.39333 | F46: =Assumptions!G141 -> 136.92 | G46: =Assumptions!H141 -> 139.52 | H46: =Assumptions!I141 -> 109.25667
B47: Imported coal exposure | D47: =60%*D46 -> 110.328 | E47: =60%*E46 -> 222.236 | F47: =60%*F46 -> 82.152 | G47: =60%*G46 -> 83.712 | H47: =60%*H46 -> 65.554
B48: FX Impact | E48: =E47*E45 -> 128.14758 | F48: =F47*F45 -> 20.463135 | G48: =G47*G45 -> 54.152218 | H48: =H47*H45 -> -4.7755424
B49: Volume Effect
...

Sheet Assumptions
B2: Historic Source | C2: Assumptions | D2: Unit | E2: 2021 | F2: =E2+1 -> 2022 | G2: =F2+1 -> 2023 | H2: =G2+1 -> 2024 | I2: =H2+1 -> 2025 | J2: =I2+1 -> 2026 | K2: =J2+1 -> 2027 | L2: =K2+1 -> 2028 | M2: =L2+1 -> 2029 | N2: =M2+1 -> 2030 | P2: Fcsting Source
C4: Economic Data
B5: World Bank | C5: Egypt Real GDP Growth (%) | D5: % | E5: 0.033 | F5: 0.066 | G5: 0.038 | H5: 0.024 | I5: 0.044 | J5: 0.042 | K5: 0.048 | L5: 0.045 | M5: 0.045 | N5: 0.045
C6: Exchange Rate/USD | D6: USD | E6: 15.66 | F6: 24.69 | G6: 30.84 | H6: 50.79 | I6: 47.09 | J6: 50.96 | K6: 50.23 | L6: 51.23 | M6: 52.26 | N6: 52.72
C7: Exchange Rate /EURO | D7: EUR | E7: 17.7928 | F7: 26.2728 | G7: 34.2712 | H7: 52.8472 | I7: 55.9255
