Workbook

Sheet Dashboard
D2: Rameda Pharmaceutical
I3: Recommendation | J3: =IF($C$10>=30%,"Buy",IF($C$10>=0,"Hold","Sell")) -> Buy
B5: Company overview | E5: methodologies | H5: Key Statisitics | K5: Market Data | N5: Shares Ownership | R5: Sensitivity Analysis in numbers "DCF model"
B6: Ticker | C6: RMDA | E6: DCF | H6: IPO | K6: Share price
B7: Stock exchange | C7: EGX30 | E7: Market EV/EBITDA | H7: Incorporated | K7: Share Outstanding
B8: Current price | E8: Market P/B | H8: Chairman | K8: Net Debt
B9: Target side | E9: Own Firm P/E | H9: Headquarters | K9: Enterprise value
B10: =IF(C10>0,"Upside","Downside") -> Upside | C10: =IFERROR(C9/C8-1,"") | E10: Own Firm EV/EBITDA | H10: Primary industry | K10: Equity value
E11: Own Firm P/E | H11: Sector
E12: Overall valuation | N12: Total | O12: =SUM(O6:O11) -> 0
B15: Key financials | N15: Scenario Switcher | O15: 0 | P15: 2
B16: Accounts | C16: 2020 | D16: 2021 | E16: =D16+1 -> 2022 | F16: =E16+1 -> 2023 | G16: =F16+1 -> 2024 | H16: =G16+1 -> 2025 | I16: =H16+1 -> 2026 | J16: =I16+1 -> 2027 | K16: =J16+1 -> 2028 | L16: =K16+1 -> 2029
B17: Revenue | C17: ='Financial Statements'!D4 -> 960.16935 | D17: ='Financial Statements'!E4 -> 1246.4346 | E17: ='Financial Statements'!F4 -> 1483.9514 | F17: ='Financial Statements'!G4 -> 1922.3507 | G17: ='Financial Statements'!H4 -> 2768.6884 | H17: ='Financial Statements'!I4 -> 4056.3218 | I17: ='Financial Statements'!J4 -> 4479.4008 | J17: ='Financial Statements'!K4 -> 5020.6274 | ... L17: ='Financial Statements'!M4 -> 6060.7561 | N17: Formating Notice "When navigating the excel"
B18: GR % | D18: =D17/C17-1 -> 0.29814041 | E18: =E17/D17-1 -> 0.19055696 | F18: =F17/E17-1 -> 0.29542698 | G18: =G17/F17-1 -> 0.44026186 | H18: =H17/G17-1 -> 0.46506982 | I18: =I17/H17-1 -> 0.10430112 | J18: =J17/I17-1 -> 0.12082569 | K18: =K17/J17-1 -> 0.083848841 | L18: =L17/K17-1 -> 0.11378175
B19: EBITDA | C19: ='Financial Statements'!D20 -> 238.10116 | D19: ='Financial Statements'!E20 -> 315.39041 | E19: ='Financial Statements'!F20 -> 397.91412 | F19: ='Financial Statements'!G20 -> 505.70628 | G19: ='Financial Statements'!H20 -> 771.24945 | H19: ='Financial Statements'!I20 -> 1084.681 | I19: ='Financial Statements'!J20 -> 1270.6522 | J19: ='Financial Statements'!K20 -> 1437.0117 | ... L19: ='Financial Statements'!M20 -> 1699.2453
B20: EBITDA Margin | C20: =IFERROR(C19/C$17,"") -> 0.2479783 | D20: =IFERROR(D19/D$17,"") -> 0.25303405 | E20: =IFERROR(E19/E$17,"") -> 0.26814497 | F20: =IFERROR(F19/F$17,"") -> 0.2630666 | G20: =IFERROR(G19/G$17,"") -> 0.2785613 | H20: =IFERROR(H19/H$17,"") -> 0.26740506 | I20: =IFERROR(I19/I$17,"") -> 0.28366566 | J20: =IFERROR(J19/J$17,"") -> 0.28622154 | ... L20: =IFERROR(L19/L$17,"") -> 0.28036853
B21: Net profit | C21: ='Financial Statements'!D38 -> 111.73066 | D21: ='Financial Statements'!E38 -> 180.28439 | E21: ='Financial Statements'!F38 -> 253.07219 | F21: ='Financial Statements'!G38 -> 253.38313 | G21: ='Financial Statements'!H38 -> 401.9611 | H21: ='Financial Statements'!I38 -> 561.23863 | I21: ='Financial Statements'!J38 -> 676.58576 | J21: ='Financial Statements'!K38 -> 915.88298 | ... L21: ='Financial Statements'!M38 -> 1158.4608
B22: Net profit Margin | C22: =IFERROR(C21/C$17,"") -> 0.11636557 | D22: =IFERROR(D21/D$17,"") -> 0.14464007 | E22: =IFERROR(E21/E$17,"") -> 0.17053941 | F22: =IFERROR(F21/F$17,"") -> 0.131809 | G22: =IFERROR(G21/G$17,"") -> 0.14518105 | H22: =IFERROR(H21/H$17,"") -> 0.13836146 | I22: =IFERROR(I21/I$17,"") -> 0.15104381 | J22: =IFERROR(J21/J$17,"") -> 0.18242401 | ... L22: =IFERROR(L21/L$17,"") -> 0.1911413 | N22: Links
B24: Toll manufacturing
B25: Export
B26: Priv Sales
B27: Tenders
B28: Overall sales
B29: RMDA Market share
B31: EPS
B32: EV/Sales
B33: EV/EBITDA
B34: P/B
B35: P/E
B36: Z-score

Sheet BS - Footnotes BD
B1: Balance sheet Breakdown | C1: 2020 | D1: 2021 | E1: 2022 | F1: 2023 | G1: 2024 | H1: =G1+1 -> 2025 | I1: =H1+1 -> 2026 | J1: =I1+1 -> 2027 | K1: =J1+1 -> 2028 | L1: =K1+1 -> 2029
B2: Assests Breakdown
B3: Non-Current Assets Breakdown
B4: Fixed Assets Breakdown
B5: Beginning Balance | C5: 2020 | D5: 2021 | E5: 2022 | F5: 2023 | G5: 2024 | H5: 2025 | I5: 2026 | J5: 2027 | K5: 2028 | L5: 2029
B6: Freehold Land | C6: 18.64 | D6: 18.64 | E6: 18.64 | F6: 18.64 | G6: 18.64 | H6: 18.64
B7: Buildings | C7: 227.84 | D7: 257.23 | E7: 273.34 | F7: 279.17 | G7: 288.43 | H7: 292.19
B8: Machinery & equipment | C8: 313.6 | D8: 397.71 | E8: 414.77 | F8: 444.86 | G8: 482.79 | H8: 502.23
B9: Transportation & dragging equipment | C9: 12.44 | D9: 13.06 | E9: 13.4 | F9: 16.34 | G9: 16.09 | H9: 18.26
B10: Laboratory equipment | C10: 17.13 | D10: 20.29 | E10: 28.26 | F10: 31.98 | G10: 35.19 | H10: 35.73
B11: Tools | C11: 3.75 | D11: 5.69 | E11: 6.02 | F11: 7.35 | G11: 11.57 | H11: 14.8
B12: Office furniture & fixtures | C12: 21.8 | D12: 25.39 | E12: 29.12 | F12: 33.11 | G12: 39.42 | H12: 46.76
B13: Assets under construction | C13: 66.33 | D13: 26.59 | E13: 27.04 | F13: 12.86 | G13: 38.09 | H13: 64.61
B14: Total Beginning Balance | C14: =SUM(C6:C13) -> 681.53 | D14: =SUM(D6:D13) -> 764.6 | E14: =SUM(E6:E13) -> 810.59 | F14: =SUM(F6:F13) -> 844.31 | G14: =SUM(G6:G13) -> 930.22 | H14: =SUM(H6:H13) -> 993.22 | I14: =SUM(I6:I13) -> 0 | J14: =SUM(J6:J13) -> 0 | ... L14: =SUM(L6:L13) -> 0
B15: Additions
B16: Freehold Land | C16: 0 | D16: 0 | E16: 0 | F16: 0 | G16: 0
B17: Buildings | C17: 6.99 | D17: 2.63 | E17: 5.27 | F17: 4.8 | G17: 3.76
B18: Machinery & equipment | C18: 8.43 | D18: 6.39 | E18: 9.94 | F18: 5.09 | G18: 19.48
B19: Transportation & dragging equipment | C19: 0.68 | D19: 0.34 | E19: 1.9 | F19: 0 | G19: 2.17
B20: Laboratory equipment | C20: 2.97 | D20: 3.45 | E20: 2.18 | F20: 3.2 | G20: 0.54
B21: Tools | C21: 1.29 | D21: 0.36 | E21: 1.33 | F21: 4.23 | G21: 3.28
B22: Office furniture & fixtures | C22: 4.57 | D22: 1.31 | E22: 4.15 | F22: 5.35 | G22: 9.19
B23: Assets under construction | C23: 60.04 | D23: 38.19 | E23: 9.61 | F23: 68.38 | G23: 26.52
B24: Total Additions | C24: =SUM(C16:C23) -> 84.97 | D24: =SUM(D16:D23) -> 52.67 | E24: =SUM(E16:E23) -> 34.38 | F24: =SUM(F16:F23) -> 91.05 | G24: =SUM(G16:G23) -> 64.94 | H24: =SUM(H16:H23) -> 0 | I24: =SUM(I16:I23) -> 0 | J24: =SUM(J16:J23) -> 0 | ... L24: =SUM(L16:L23) -> 0
B25: Transferred from Sales under Construction
B26: Freehold Land | C26: 0 | D26: 0 | E26: 0 | F26: 0 | G26: 0
B27: Buildings | C27: 22.4 | D27: 13.49 | E27: 0.56 | F27: 4.46 | G27: 2.575827
B28: Machinery & equipment | C28: 76.09 | D28: 13.64 | E28: 20.33 | F28: 37.27 | G28: 28.57
B29: Transportation & dragging equipment | C29: 0 | D29: 0 | E29: 1.04 | F29: 0 | G29: 0
B30: Laboratory equipment | C30: 0.53 | D30: 7.94 | E30: 1.81 | F30: 0 | G30: 0
B31: Tools | C31: 0.65 | D31: 0 | E31: 0 | F31: 0 | G31: 0
B32: Office furniture & fixtures | C32: 0.12 | D32: 2.67 | E32: 0.05 | F32: 1.41 | G32: 0
B33: Assets under construction | C33: -99.78 | D33: -37.74 | E33: -23.79 | F33: -43.14 | G33: -31.141189
B34: Total Construction | C34: =SUM(C26:C33) -> 0.01 | D34: =SUM(D26:D33) -> 0 | E34: =SUM(E26:E33) -> 0 | F34: =SUM(F26:F33) -> 0 | G34: =SUM(G26:G33) -> 0.004638 | H34: =SUM(H26:H33) -> 0 | I34: =SUM(I26:I33) -> 0 | J34: =SUM(J26:J33) -> 0 | ... L34: =SUM(L26:L33) -> 0
B35: Disposals
B36: Freehold Land | C36: 0 | D36: 0 | E36: 0 | F36: 0 | G36: 0
B37: Buildings | C37: 0 | D37: 0 | E37: 0 | F37: 0 | G37: 0
B38: Machinery & equipment | C38: -0.41 | D38: -2.97 | E38: -0.18 | F38: -4.43 | G38: -0.04
B39: Transportation & dragging equipment | C39: -0.07 | D39: 0 | E39: 0 | F39: -0.25 | G39: 0
B40: Laboratory equipment | C40: -0.34 | D40: -3.42 | E40: -0.27 | F40: 0 | G40: 0
...

Sheet Financial Statements
B2: Income Statement
B3: For 2020-2024 | D3: 2020 | E3: 2021 | F3: 2022 | G3: 2023 | H3: 2024 | I3: =H3+1 -> 2025 | J3: =I3+1 -> 2026 | K3: =J3+1 -> 2027 | L3: =K3+1 -> 2028 | M3: =L3+1 -> 2029
B4: Revenues | D4: 960.16935 | E4: 1246.4346 | F4: 1483.9514 | G4: 1922.3507 | H4: 2768.6884 | I4: ='IS- Breakdown'!H14 -> 4056.3218 | J4: ='IS- Breakdown'!I14 -> 4479.4008 | K4: ='IS- Breakdown'!J14 -> 5020.6274 | L4: ='IS- Breakdown'!K14 -> 5441.6012 | M4: ='IS- Breakdown'!L14 -> 6060.7561 | N4: =_xlfn.RRI(4,I4,M4) -> 0.10560145
B5: COGS | D5: =-'IS- Breakdown'!C95+'IS- Breakdown'!C90 -> -463.40793 | E5: =-'IS- Breakdown'!D95+'IS- Breakdown'!D90 -> -629.13266 | F5: =-'IS- Breakdown'!E95+'IS- Breakdown'!E90 -> -705.33224 | G5: =-'IS- Breakdown'!F95+'IS- Breakdown'!F90 -> -950.67706 | H5: =-'IS- Breakdown'!G95+'IS- Breakdown'!G90 -> -1409.1501 | I5: =-'IS- Breakdown'!H95 -> -1992.7111 | J5: =-'IS- Breakdown'!I97 -> -2160.5735 | K5: =-'IS- Breakdown'!J97 -> -2420.6717 | L5: =-'IS- Breakdown'!K97 -> -2656.4711 | M5: =-'IS- Breakdown'!L97 -> -2982.111 | N5: =_xlfn.RRI(4,I5,M5) -> 0.10603753
B6: Gross Profit | D6: =D5+D4 -> 496.76142 | E6: =E5+E4 -> 617.30197 | F6: =F4+F5 -> 778.61919 | G6: =G4+G5 -> 971.67366 | H6: =H4+H5 -> 1359.5383 | I6: =I4+I5 -> 2063.6107 | J6: =J4+J5 -> 2318.8272 | K6: =K4+K5 -> 2599.9558 | L6: =L4+L5 -> 2785.1301 | M6: =M4+M5 -> 3078.6451
B7: Gross profit margin | D7: =D6/D4 -> 0.51736855 | E7: =E6/E4 -> 0.49525419 | F7: =F6/F4 -> 0.52469318 | G7: =G6/G4 -> 0.50546118 | H7: =H6/H4 -> 0.49104056 | I7: =I6/I4 -> 0.50873939 | J7: =J6/J4 -> 0.5176646 | K7: =K6/K4 -> 0.51785475 | ... M7: =M6/M4 -> 0.50796386
B8: Mark-up | D8: =ABS(D6/D5) -> 1.0719744 | E8: =ABS(E6/E5) -> 0.98119525 | F8: =ABS(F6/F5) -> 1.1039042 | G8: =ABS(G6/G5) -> 1.022086 | H8: =ABS(H6/H5) -> 0.96479309 | I8: =ABS(I6/I5) -> 1.0355794 | J8: =ABS(J6/J5) -> 1.0732461 | K8: =ABS(K6/K5) -> 1.0740638 | ... M8: =ABS(M6/M5) -> 1.0323711
B10: Selling and marketing expenses | D10: =-214.204258+4.19716 -> -210.0071 | E10: =-251.984883+4.497393 -> -247.48749 | F10: =-296.417891+4.901259 -> -291.51663 | G10: =-363.580501+5.122198 -> -358.4583 | H10: =-447.876799+5.314134 -> -442.56266 | I10: =-'IS- Breakdown'!H146 -> -762.03851 | J10: =-'IS- Breakdown'!I146 -> -819.15825 | K10: =-'IS- Breakdown'!J146 -> -905.47461 | L10: =-'IS- Breakdown'!K146 -> -966.61041 | M10: =-'IS- Breakdown'!L146 -> -1069.2244
B11: S&M Margin | D11: =-D10/D4 -> 0.21871881 | E11: =-E10/E4 -> 0.19855633 | F11: =-F10/F4 -> 0.19644621 | G11: =-G10/G4 -> 0.18646873 | H11: =-H10/H4 -> 0.1598456 | I11: =-I10/I4 -> 0.18786441 | J11: =-J10/J4 -> 0.18287228 | K11: =-K10/K4 -> 0.18035089 | ... M11: =-M10/M4 -> 0.17641766
B12: General and administrative expenses | D12: =-44.735538+1.829115 -> -42.906423 | E12: =-51.901349+1.907312 -> -49.994037 | F12: =-65.91287+2.006816 -> -63.906054 | G12: =-82.330195+2.003262 -> -80.326933 | H12: =-112.423776+2.244169 -> -110.17961 | I12: =-'IS- Breakdown'!H155 -> -170.22874 | J12: =-'IS- Breakdown'!I155 -> -187.92168 | K12: =-'IS- Breakdown'!J155 -> -210.64427 | L12: =-'IS- Breakdown'!K155 -> -228.10969 | M12: =-'IS- Breakdown'!L155 -> -254.03951
B13: Impairment of trade and notes receivable | D13: -1.802092 | E13: -0.1056 | F13: -3.643441 | G13: -3.808579 | H13: -11.442943 | I13: ='BS-Breakdown'!H176-'BS-Breakdown'!G176 -> -9.3790789 | J13: ='BS-Breakdown'!I176-'BS-Breakdown'!H176 -> -3.7057049 | K13: ='BS-Breakdown'!J176-'BS-Breakdown'!I176 -> -4.7405492 | L13: ='BS-Breakdown'!K176-'BS-Breakdown'!J176 -> -3.6872664 | M13: ='BS-Breakdown'!L176-'BS-Breakdown'!K176 -> -5.4231146
B14: Provisions | D14: -1.6 | E14: -1.25 | F14: 0 | G14: -0.673282 | H14: -0.5 | I14: ='BS-Breakdown'!G259-'BS-Breakdown'!H259 -> -4.4405911 | J14: ='BS-Breakdown'!H259-'BS-Breakdown'!I259 -> -1.1211002 | K14: ='BS-Breakdown'!I259-'BS-Breakdown'!J259 -> -1.4341753 | L14: ='BS-Breakdown'!J259-'BS-Breakdown'!K259 -> -1.1155219 | M14: ='BS-Breakdown'!K259-'BS-Breakdown'!L259 -> -1.6406743
B15: Share based payment expenses | D15: 0 | E15: 0 | F15: -17.84792 | G15: -17.768011 | H15: -16.286564 | I15: =I16*I$4 -> -22.027905 | J15: =J16*J$4 -> -24.325441 | K15: =K16*K$4 -> -27.264579 | L15: =L16*L$4 -> -29.550682 | M15: =M16*M$4 -> -32.91301
B16: % of sales | D16: =D15/D$4 -> 0 | E16: =E15/E$4 -> 0 | F16: =F15/F$4 -> -0.012027294 | G16: =G15/G$4 -> -0.0092428561 | H16: =H15/H$4 -> -0.0058824113 | I16: =AVERAGE(D16:H16) -> -0.0054305123 | J16: =I16 -> -0.0054305123 | K16: =J16 -> -0.0054305123 | L16: =K16 -> -0.0054305123 | M16: =L16 -> -0.0054305123
B17: Contribution for health insurance | D17: -2.56337 | E17: -3.272995 | F17: -3.975441 | G17: -5.109505 | H17: -7.471037 | I17: =I18*I$4 -> -10.814882 | J17: =J18*J$4 -> -11.942886 | K17: =K18*K$4 -> -13.385894 | L17: =L18*L$4 -> -14.508286 | M17: =M18*M$4 -> -16.159064
B18: % of sales | D18: =D17/D$4 -> -0.0026697061 | E18: =E17/E$4 -> -0.0026258858 | F18: =F17/F$4 -> -0.0026789563 | G18: =G17/G$4 -> -0.0026579463 | H18: =H17/H$4 -> -0.0026984029 | I18: =AVERAGE(D18:H18) -> -0.0026661795 | J18: =I18 -> -0.0026661795 | K18: =J18 -> -0.0026661795 | L18: =K18 -> -0.0026661795 | M18: =L18 -> -0.0026661795
B20: EBITDA | D20: =D6+SUM(D10:D17) -> 238.10116 | E20: =E6+SUM(E10:E17) -> 315.39041 | F20: =F6+SUM(F10:F17) -> 397.91412 | G20: =G6+SUM(G10:G17) -> 505.70628 | H20: =H6+SUM(H10:H17) -> 771.24945 | I20: =+I6+I10+I12+I13+I14+I15+I17 -> 1084.681 | J20: =+J6+J10+J12+J13+J14+J15+J17 -> 1270.6522 | K20: =+K6+K10+K12+K13+K14+K15+K17 -> 1437.0117 | L20: =+L6+L10+L12+L13+L14+L15+L17 -> 1541.5482 | M20: =+M6+M10+M12+M13+M14+M15+M17 -> 1699.2453
B21: EBITDA Margin | D21: =D20/D4 -> 0.2479783 | E21: =E20/E4 -> 0.25303405 | F21: =F20/F4 -> 0.26814497 | G21: =G20/G4 -> 0.2630666 | H21: =H20/H4 -> 0.2785613 | I21: =I20/I4 -> 0.26740506 | J21: =J20/J4 -> 0.28366566 | K21: =K20/K4 -> 0.28622154 | ... M21: =M20/M4 -> 0.28036853
B23: Depreciation | D23: -46.330194 | E23: -31.877452 | F23: -35.413949 | G23: -38.110835 | H23: -43.718707 | I23: ='BS-Breakdown'!H83 -> -45.612299 | J23: ='BS-Breakdown'!I83 -> -46.485168 | K23: ='BS-Breakdown'!J83 -> -48.989582 | L23: ='BS-Breakdown'!K83 -> -52.042177 | M23: ='BS-Breakdown'!L83 -> -55.00255
B24: Amortization | D24: =D25-D23 -> -9.871612 | E24: =E25-E23 -> -14.304121 | F24: =F25-F23 -> -30.070417 | G24: =G25-G23 -> -34.773153 | H24: =H25-H23 -> -39.713887 | I24: ='BS-Breakdown'!H131+'BS-Breakdown'!H144 -> -46.106065 | J24: ='BS-Breakdown'!I131+'BS-Breakdown'!I144 -> -53.643418 | K24: ='BS-Breakdown'!J131+'BS-Breakdown'!J144 -> -58.497262 | L24: ='BS-Breakdown'!K131+'BS-Breakdown'!K144 -> -68.977208 | M24: ='BS-Breakdown'!L131+'BS-Breakdown'!L144 -> -68.977208
B25: Depreciation and amortization Total | D25: -56.201806 | E25: -46.181573 | F25: -65.484366 | G25: -72.883988 | H25: -83.432594 | I25: =SUM(I23:I24) -> -91.718364 | J25: =SUM(J23:J24) -> -100.12859 | K25: =SUM(K23:K24) -> -107.48684 | L25: =SUM(L23:L24) -> -121.01938 | M25: =SUM(M23:M24) -> -123.97976
B26: EBIT | D26: =D20+SUM(D23:D24) -> 181.89935 | E26: =E20+SUM(E23:E24) -> 269.20883 | F26: =F20+SUM(F23:F24) -> 332.42975 | G26: =G20+SUM(G23:G24) -> 432.82229 | H26: =H20+SUM(H23:H24) -> 687.81686 | I26: =+I20+I25 -> 992.96263 | J26: =+J20+J25 -> 1170.5236 | K26: =+K20+K25 -> 1329.5248 | L26: =+L20+L25 -> 1420.5288 | M26: =+M20+M25 -> 1575.2655
B27: EBIT Margin | D27: =D26/D4 -> 0.18944507 | E27: =E26/E4 -> 0.21598311 | F27: =F26/F4 -> 0.2240166 | G27: =G26/G4 -> 0.22515261 | H27: =H26/H4 -> 0.24842696 | I27: =I26/I4 -> 0.24479385 | J27: =J26/J4 -> 0.26131254 | K27: =K26/K4 -> 0.26481249 | ... M27: =M26/M4 -> 0.25991238
B29: Finance income | D29: 64.160293 | E29: 59.973 | F29: 56.732176 | G29: 62.902521 | H29: 65.852148 | I29: ='IS- Breakdown'!H166 -> 45.747704 | J29: ='IS- Breakdown'!I166 -> 15.428505 | K29: ='IS- Breakdown'!J166 -> 6.8757761 | L29: ='IS- Breakdown'!K166 -> 11.654233 | M29: ='IS- Breakdown'!L166 -> 15.598651
B30: Finance expenses | D30: -100.05893 | E30: -94.817656 | F30: -92.084277 | G30: -194.25931 | H30: -310.94187 | I30: =-'IS- Breakdown'!H172 -> -329.80701 | J30: =-'IS- Breakdown'!H172 -> -329.80701 | K30: =-'IS- Breakdown'!I172 -> -173.52313 | L30: =-'IS- Breakdown'!J172 -> -118.47001 | M30: =-'IS- Breakdown'!K172 -> -118.9
B31: Net foregin exchange gain | D31: -1.695406 | E31: -0.596919 | F31: 25.651093 | G31: 18.683006 | H31: 56.240536 | I31: 0 | J31: 0 | K31: 0 | L31: 0 | M31: 0
B32: Other income | D32: 1.019971 | E32: 0.041606 | F32: 5.90985 | G32: 7.476152 | H32: 27.305011 | I32: =I33*I4 -> 15.275551 | J32: =J33*J4 -> 16.868808 | K32: =K33*K4 -> 18.906993 | L32: =L33*L4 -> 20.492323 | M32: =M33*M4 -> 22.823975
B33: % of sales | D33: =D32/D$4 -> 0.0010622824 | E33: =E32/E$4 -> 3.338001e-05 | F33: =F32/F$4 -> 0.0039825091 | G33: =G32/G$4 -> 0.0038890676 | H33: =H32/H$4 -> 0.0098620743 | I33: =AVERAGE(D33:H33) -> 0.0037658627 | J33: =I33 -> 0.0037658627 | K33: =J33 -> 0.0037658627 | L33: =K33 -> 0.0037658627 | M33: =L33 -> 0.0037658627
B34: EBT | D34: =D26+SUM(D29:D32) -> 145.32528 | E34: =E26+SUM(E29:E32) -> 233.80886 | F34: =F26+SUM(F29:F32) -> 328.63859 | G34: =G26+SUM(G29:G32) -> 327.62466 | H34: =H26+SUM(H29:H32) -> 526.27269 | I34: =+I32+I31+I30+I29+I26 -> 724.17888 | J34: =+J32+J31+J30+J29+J26 -> 873.01388 | K34: =+K32+K31+K30+K29+K26 -> 1181.7845 | L34: =+L32+L31+L30+L29+L26 -> 1334.2054 | M34: =+M32+M31+M30+M29+M26 -> 1494.7882
B35: EBT Margin | D35: =D34/D4 -> 0.1513538 | E35: =E34/E4 -> 0.18758213 | F35: =F34/F4 -> 0.22146183 | G35: =G34/G4 -> 0.17042918 | H35: =H34/H4 -> 0.19008014 | I35: =I34/I4 -> 0.17853092 | J35: =J34/J4 -> 0.19489524 | K35: =K34/K4 -> 0.23538582 | ... M35: =M34/M4 -> 0.24663394
B37: Income Taxes | D37: -33.594619 | E37: -53.524475 | F37: -75.5664 | G37: -74.241526 | H37: -124.31159 | I37: =I34*-22.5% -> -162.94025 | J37: =J34*-22.5% -> -196.42812 | K37: =K34*-22.5% -> -265.90151 | L37: =L34*-22.5% -> -300.19621 | M37: =M34*-22.5% -> -336.32734
B38: Net Profit | D38: =D34+D37 -> 111.73066 | E38: =E34+E37 -> 180.28439 | F38: =F34+F37 -> 253.07219 | G38: =G34+G37 -> 253.38313 | H38: =H34+H37 -> 401.9611 | I38: =I34+I37 -> 561.23863 | J38: =J34+J37 -> 676.58576 | K38: =K34+K37 -> 915.88298 | ... M38: =M34+M37 -> 1158.4608
B39: Net Profit Margin | D39: =D38/D4 -> 0.11636557 | E39: =E38/E4 -> 0.14464007 | F39: =F38/F4 -> 0.17053941 | G39: =G38/G4 -> 0.131809 | H39: =H38/H4 -> 0.14518105 | I39: =I38/I4 -> 0.13836146 | J39: =J38/J4 -> 0.15104381 | K39: =K38/K4 -> 0.18242401 | ... M39: =M38/M4 -> 0.1911413
G40: 244.85945 | H40: 387.36687 | I40: =I38-I41 -> 546.79837 | J40: =J38-J41 -> 662.1455 | K40: =K38-K41 -> 901.44272 | L40: =L38-L41 -> 1019.5689 | M40: =M38-M41 -> 1144.0206
G41: 8.34646 | H41: 14.440262 | I41: =H41 -> 14.440262 | J41: =I41 -> 14.440262 | K41: =J41 -> 14.440262 | L41: =K41 -> 14.440262 | M41: =L41 -> 14.440262
G42: =G40+G41 -> 253.20591 | H42: =H40+H41 -> 401.80713 | I42: =I40+I41 -> 561.23863 | J42: =J40+J41 -> 676.58576 | K42: =K40+K41 -> 915.88298 | L42: =L40+L41 -> 1034.0092 | M42: =M40+M41 -> 1158.4608
B43: Checker | G43: =G42-G38 -> -0.17722488 | H43: =H42-H38 -> -0.15396319
B45: Balancesheet Statement
B46: For 2020-2024 | D46: 2020 | E46: 2021 | F46: 2022 | G46: 2023 | H46: 2024 | I46: =H46+1 -> 2025 | J46: =I46+1 -> 2026 | K46: =J46+1 -> 2027 | L46: =K46+1 -> 2028 | M46: =L46+1 -> 2029
B47: Assets
...

Sheet IS- Breakdown
B3: Revenue breakdown | C3: 2020 | D3: 2021 | E3: 2022 | F3: 2023 | G3: 2024 | H3: =G3+1 -> 2025 | I3: =H3+1 -> 2026 | J3: =I3+1 -> 2027 | K3: =J3+1 -> 2028 | L3: =K3+1 -> 2029
B4: Services Toll Manufacturing Domestic | C4: 50.839648 | D4: 77.490353 | E4: 132.43683 | F4: 134.00577 | G4: 181.86566 | H4: =G4-O7+P7 -> 284.43546 | I4: =IFERROR(I37*I51,"") -> 327.22695 | J4: =IFERROR(J37*J51,"") -> 371.09195 | K4: =IFERROR(K37*K51,"") -> 400.23072 | L4: =IFERROR(L37*L51,"") -> 436.49139
B5: Export | C5: 49.93875 | D5: 87.872886 | E5: 106.50658 | F5: 180.24423 | G5: 142.20235 | H5: =G5-O8+P8 -> 172.13497 | I5: =I36*I50 -> 207.91816 | J5: =J36*J50 -> 267.7243 | K5: =K36*K50 -> 307.63679 | L5: =L36*L50 -> 355.10627 | O5: TTM for Revenue Q3 2025F page no. 11 | P5: FS Report Q3
B6: Private Sales | C6: 659.7097 | D6: 829.08115 | E6: 1084.237 | F6: 1418.6302 | G6: 2208.1899 | H6: =G6-O9+P9 -> 2956.9811 | I6: =IFERROR(I35*I49,"") -> 3254.4621 | J6: =IFERROR(J35*J49,"") -> 3614.3993 | K6: =IFERROR(K35*K49,"") -> 3915.3239 | L6: =IFERROR(L35*L49,"") -> 4357.7937 | O6: 2024 | P6: 2025
B7: Tenders | C7: 199.68525 | D7: 251.99024 | E7: 160.77102 | F7: 189.47047 | G7: 236.4305 | H7: =G7-O10+P10 -> 534.47018 | I7: =I34*I48 -> 568.75719 | J7: =J34*J48 -> 632.14158 | K7: =K34*K48 -> 667.23157 | L7: =L34*L48 -> 742.40776 | N7: Toll | O7: 117.18985 | P7: 219.75965
B8: Total | C8: =SUM(C4:C7) -> 960.17335 | D8: =SUM(D4:D7) -> 1246.4346 | E8: =SUM(E4:E7) -> 1483.9514 | F8: =SUM(F4:F7) -> 1922.3507 | G8: =SUM(G4:G7) -> 2768.6884 | H8: =SUM(H4:H7) -> 3948.0217 | I8: =SUM(I4:I7) -> 4358.3644 | J8: =SUM(J4:J7) -> 4885.3571 | ... L8: =SUM(L4:L7) -> 5891.7992 | N8: X | O8: 139.12338 | P8: 169.056
N9: PS | O9: 1411.878 | P9: 2160.6692
A10: Note 21 | B10: Revenue | C10: 2020 | D10: 2021 | E10: 2022 | F10: 2023 | G10: 2024 | H10: =G10+1 -> 2025 | I10: =H10+1 -> 2026 | J10: =I10+1 -> 2027 | K10: =J10+1 -> 2028 | L10: =K10+1 -> 2029 | N10: T | O10: 116.17736 | P10: 414.21705
B11: Sale of goods (net) | C11: 909.3297 | D11: 1168.9443 | E11: 1351.5146 | F11: 1788.3449 | G11: =SUM(G5:G7) -> 2586.8228 | H11: =SUM(H5:H7) -> 3663.5863 | I11: =SUM(I5:I7) -> 4031.1375 | J11: =SUM(J5:J7) -> 4514.2652 | K11: =SUM(K5:K7) -> 4890.1923 | L11: =SUM(L5:L7) -> 5455.3078 | N11: Total | O11: =SUM(O7:O10) -> 1784.3686 | P11: =SUM(P7:P10) -> 2963.7019
B12: Cosmetics | G12: =3.5%*G14 -> 96.904095 | H12: =G12*(1+Assumptions!$Q36) -> 108.30012 | I12: =H12*(1+Assumptions!$Q36) -> 121.03632 | J12: =I12*(1+Assumptions!$Q36) -> 135.27032 | K12: =J12*(1+Assumptions!$Q36) -> 151.17825 | L12: =K12*(1+Assumptions!$Q36) -> 168.95697 | M12: =_xlfn.RRI(4,H12,L12) -> 0.11760104 | O12: TTM for Volume Q3 2025F
B13: Toll Maunfacturing services revenue | C13: 50.839648 | D13: 77.490353 | E13: 132.43683 | F13: 134.00577 | G13: =G4 -> 181.86566 | H13: =H4 -> 284.43546 | I13: =I4 -> 327.22695 | J13: =J4 -> 371.09195 | K13: =K4 -> 400.23072 | L13: =L4 -> 436.49139 | O13: 2024 | P13: 2025
B14: Total | C14: =SUM(C11:C13) -> 960.16935 | D14: =SUM(D11:D13) -> 1246.4346 | E14: =SUM(E11:E13) -> 1483.9514 | F14: =SUM(F11:F13) -> 1922.3507 | G14: =G11+G13 -> 2768.6884 | H14: =SUM(H11:H13) -> 4056.3218 | I14: =SUM(I11:I13) -> 4479.4008 | J14: =SUM(J11:J13) -> 5020.6274 | K14: =SUM(K11:K13) -> 5441.6012 | L14: =SUM(L11:L13) -> 6060.7561 | N14: Toll | O14: 43.4 | P14: 56.5
N15: X | O15: 3.9 | P15: 4.8
B16: Market Share | C16: =(C14*1000000)/(Assumptions!C25*1000000000) -> 0.014301429 | D16: =(D14*1000000)/(Assumptions!D25*1000000000) -> 0.011448624 | E16: =(E14*1000000)/(Assumptions!E25*1000000000) -> 0.011592827 | F16: =(F14*1000000)/(Assumptions!F25*1000000000) -> 0.010631177 | G16: =(G14*1000000)/(Assumptions!G25*1000000000) -> 0.011962258 | H16: =(H14*1000000)/(Assumptions!H25*1000000000) -> 0.013799595 | I16: =(I14*1000000)/(Assumptions!I25*1000000000) -> 0.013908461 | J16: =(J14*1000000)/(Assumptions!J25*1000000000) -> 0.014626524 | ... L16: =(L14*1000000)/(Assumptions!L25*1000000000) -> 0.015751675 | N16: PS | O16: 25.4 | P16: 34.1
B17: YoY % | D17: =D14/C14-1 -> 0.29814041 | E17: =E14/D14-1 -> 0.19055696 | F17: =F14/E14-1 -> 0.29542698 | G17: =G14/F14-1 -> 0.44026186 | H17: =H14/G14-1 -> 0.46506982 | I17: =I14/H14-1 -> 0.10430112 | J17: =J14/I14-1 -> 0.12082569 | K17: =K14/J14-1 -> 0.083848841 | L17: =L14/K14-1 -> 0.11378175 | N17: T | O17: 4.2 | P17: 14.6
B18: CAGR | C18: =_xlfn.RRI(COLUMNS(C14:G14)-1,C14,G14) -> 0.30311145 | H18: =_xlfn.RRI(COLUMNS(H14:L14)-1,H14,L14) -> 0.10560145 | N18: Total | O18: =SUM(O14:O17) -> 76.9 | P18: =SUM(P14:P17) -> 110
B20: % Revenue forecasted | C20: 2020 | D20: 2021 | E20: 2022 | F20: 2023 | G20: 2024 | H20: =G20+1 -> 2025 | I20: =H20+1 -> 2026 | J20: =I20+1 -> 2027 | K20: =J20+1 -> 2028 | L20: =K20+1 -> 2029
B21: Sale of goods (net) | G21: =(G11/G$14)-G22 -> 0.89931343 | H21: =H11/H$14 -> 0.90317938 | I21: =I11/I$14 -> 0.89992785 | J21: =J11/J$14 -> 0.89914363 | K21: =K11/K$14 -> 0.89866788 | L21: =L11/L$14 -> 0.90010349
B22: Cosmetics | G22: =G12/G$14 -> 0.035 | H22: =H12/H$14 -> 0.026699094 | I22: =I12/I$14 -> 0.027020651 | J22: =J12/J$14 -> 0.026942911 | K22: =K12/K$14 -> 0.027781942 | L22: =L12/L$14 -> 0.027877209
B23: Toll Maunfacturing services revenue | G23: =G13/G$14 -> 0.065686575 | H23: =H13/H$14 -> 0.070121521 | I23: =I13/I$14 -> 0.073051501 | J23: =J13/J$14 -> 0.073913461 | K23: =K13/K$14 -> 0.073550174 | L23: =L13/L$14 -> 0.072019296
B24: Total | G24: =SUM(G21:G23) -> 1 | H24: =SUM(H21:H23) -> 1 | I24: =SUM(I21:I23) -> 1 | J24: =SUM(J21:J23) -> 1 | K24: =SUM(K21:K23) -> 1 | L24: =SUM(L21:L23) -> 1
B26: Utilization & Capacity | C26: 2020 | D26: 2021 | E26: 2022 | F26: 2023 | G26: 2024 | H26: =G26+1 -> 2025 | I26: =H26+1 -> 2026 | J26: =I26+1 -> 2027 | K26: =J26+1 -> 2028 | L26: =K26+1 -> 2029
B27: Capacity | C27: 424.1 | D27: 424.1 | E27: 424.1 | F27: 424.1 | G27: 424.1 | H27: 424.1 | I27: 424.1 | J27: 424.1 | K27: 424.1 | L27: 424.1
B28: Utilization (Tender) | C28: =C34/C27 -> 0.071266211 | D28: =D34/D27 -> 0.062640887 | E28: =E34/E27 -> 0.038499882 | F28: =F34/F27 -> 0.030888941 | G28: =G34/G27 -> 0.019099269 | H28: =H34/H$27 -> 0.043621787 | I28: =I34/I$27 -> 0.041707265 | J28: =J34/J$27 -> 0.042802656 | K28: =K34/K$27 -> 0.042823335 | L28: =L34/L$27 -> 0.045249942
B29: Utilization (Private Sales) | C29: =C35/C27 -> 0.063923603 | D29: =D35/D27 -> 0.074529592 | E29: =E35/E27 -> 0.085135581 | F29: =F35/F27 -> 0.075030182 | G29: =G35/$G$27 -> 0.093138411 | H29: =H35/H$27 -> 0.11365244 | I29: =I35/I$27 -> 0.11238653 | J29: =J35/J$27 -> 0.11525047 | K29: =K35/K$27 -> 0.11833735 | L29: =L35/L$27 -> 0.12508131
B30: Utilization (Exports) | C30: =C36/C27 -> 0.0080853572 | D30: =D36/D27 -> 0.0065927847 | E30: =E36/E27 -> 0.014168828 | F30: =F36/F27 -> 0.016518746 | G30: =G36/$G$27 -> 0.0099033247 | H30: =H36/H$27 -> 0.012025466 | I30: =I36/I$27 -> 0.013180856 | J30: =J36/J$27 -> 0.01561383 | K30: =K36/K$27 -> 0.016658819 | L30: =L36/L$27 -> 0.017988153
B31: Utilization (Toll Manufacturing) | C31: =C37/C27 -> 0.061219052 | D31: =D37/D27 -> 0.081296864 | E31: =E37/E27 -> 0.20398963 | F31: =F37/F27 -> 0.14966753 | G31: =G37/$G$27 -> 0.15963216 | H31: =H37/H$27 -> 0.1905211 | I31: =I37/I$27 -> 0.19693062 | J31: =J37/J$27 -> 0.20621358 | K31: =K37/K$27 -> 0.2108112 | L31: =L37/L$27 -> 0.21833863
B32: Utilization rate total | C32: =C38/C27 -> 0.20449422 | D32: =D38/D27 -> 0.22506013 | E32: =E38/E27 -> 0.34179392 | F32: =F38/F27 -> 0.2721054 | G32: =G38/G27 -> 0.28177317 | H32: =H38/H27 -> 0.3598208 | I32: =I38/I27 -> 0.36420528 | J32: =J38/J27 -> 0.37988054 | ... L32: =L38/L27 -> 0.40665804 | N32: =HARMEAN(C32:G32) -> 0.25663253 | O32: =HARMEAN(H32:L32) -> 0.37909007
B33: Volume Sold | C33: 2020 | D33: 2021 | E33: 2022 | F33: 2023 | G33: 2024 | H33: =G33+1 -> 2025 | I33: =H33+1 -> 2026 | J33: =I33+1 -> 2027 | K33: =J33+1 -> 2028 | L33: =K33+1 -> 2029 | N33: Demand inc (toll &PS)
B34: Volume Sold (Tender) | C34: 30.224 | D34: 26.566 | E34: 16.3278 | F34: 13.1 | G34: 8.1 | H34: =G34-O17+P17 -> 18.5 | I34: =FORECAST(Assumptions!I26,'IS- Breakdown'!$F$34:$H$34,Assumptions!F26:H26) -> 17.688051 | J34: =FORECAST(Assumptions!J26,'IS- Breakdown'!$F$34:$H$34,Assumptions!G26:I26) -> 18.152606 | K34: =FORECAST(Assumptions!K26,'IS- Breakdown'!$F$34:$H$34,Assumptions!H26:J26) -> 18.161376 | L34: =FORECAST(Assumptions!L26,'IS- Breakdown'!$F$34:$H$34,Assumptions!I26:K26) -> 19.190501 | N34: Export will increase on a mid-term
B35: Volume Sold (Private Sales) | C35: 27.11 | D35: 31.608 | E35: 36.106 | F35: 31.8203 | G35: 39.5 | H35: =G35-O16+P16 -> 48.2 | I35: =FORECAST(Assumptions!I20,'IS- Breakdown'!C35:H35,Assumptions!C20:H20) -> 47.663129 | J35: =FORECAST(Assumptions!J20,'IS- Breakdown'!D35:I35,Assumptions!D20:I20) -> 48.877726 | K35: =FORECAST(Assumptions!K20,'IS- Breakdown'!E35:J35,Assumptions!E20:J20) -> 50.186869 | L35: =FORECAST(Assumptions!L20,'IS- Breakdown'!F35:K35,Assumptions!F20:K20) -> 53.046985 | N35: Sudan's demand also a contributing to increased volume
B36: Volume Sold (Exports) | C36: 3.429 | D36: 2.796 | E36: 6.009 | F36: 7.0056 | G36: 4.2 | H36: =G36-O15+P15 -> 5.1 | I36: =FORECAST(Assumptions!I14,'IS- Breakdown'!C36:H36,Assumptions!C14:H14) -> 5.590001 | J36: =FORECAST(Assumptions!J14,'IS- Breakdown'!D36:I36,Assumptions!D14:I14) -> 6.6218252 | K36: =FORECAST(Assumptions!K14,'IS- Breakdown'!E36:J36,Assumptions!E14:J14) -> 7.0650053 | L36: =FORECAST(Assumptions!L14,'IS- Breakdown'!F36:K36,Assumptions!F14:K14) -> 7.6287759
B37: Volume Sold (Toll Manufacturing) | C37: 25.963 | D37: 34.478 | E37: 86.512 | F37: 63.474 | G37: 67.7 | H37: =G37-O14+P14 -> 80.8 | I37: =FORECAST(Assumptions!I20,'IS- Breakdown'!F37:H37,Assumptions!F20:H20) -> 83.518277 | J37: =FORECAST(Assumptions!J20,'IS- Breakdown'!G37:I37,Assumptions!G20:I20) -> 87.45518 | K37: =FORECAST(Assumptions!K20,'IS- Breakdown'!H37:J37,Assumptions!H20:J20) -> 89.405031 | L37: =FORECAST(Assumptions!L20,'IS- Breakdown'!I37:K37,Assumptions!I20:K20) -> 92.597413
B38: Total | C38: =SUM(C34:C37) -> 86.726 | D38: =SUM(D34:D37) -> 95.448 | E38: =SUM(E34:E37) -> 144.9548 | F38: =SUM(F34:F37) -> 115.3999 | G38: =SUM(G34:G37) -> 119.5 | H38: =SUM(H34:H37) -> 152.6 | I38: =SUM(I34:I37) -> 154.45946 | J38: =SUM(J34:J37) -> 161.10734 | ... L38: =SUM(L34:L37) -> 172.46367
B39: Own Volume | C39: =C38-C37 -> 60.763 | D39: =D38-D37 -> 60.97 | E39: =E38-E37 -> 58.4428 | F39: =F38-F37 -> 51.9259 | G39: =G38-G37 -> 51.8 | H39: =H38-H37 -> 71.8 | I39: =I38-I37 -> 70.941181 | J39: =J38-J37 -> 73.652158 | ... L39: =L38-L37 -> 79.866261
B41: Volume Sold % | C41: 2020 | D41: 2021 | E41: 2022 | F41: 2023 | G41: 2024 | H41: =G41+1 -> 2025 | I41: =H41+1 -> 2026 | J41: =I41+1 -> 2027 | K41: =J41+1 -> 2028 | L41: =K41+1 -> 2029
B42: Volume Sold (Tender) | C42: =C34/C38 -> 0.34849987 | D42: =D34/D38 -> 0.27832956 | E42: =E34/E38 -> 0.11264063 | F42: =F34/F38 -> 0.1135183 | G42: =G34/G38 -> 0.067782427 | H42: =H34/H38 -> 0.12123198 | I42: =I34/I38 -> 0.11451582 | J42: =J34/J38 -> 0.11267399 | ... L42: =L34/L38 -> 0.11127271
B43: Volume Sold (Private Sales) | C43: =C35/C38 -> 0.31259369 | D43: =D35/D38 -> 0.33115414 | E43: =E35/E38 -> 0.24908454 | F43: =F35/F38 -> 0.27573941 | G43: =G35/G38 -> 0.33054393 | H43: =H35/H38 -> 0.31585845 | I43: =I35/I38 -> 0.30858019 | J43: =J35/J38 -> 0.3033861 | ... L43: =L35/L38 -> 0.30758353
B44: Volume Sold (Exports) | C44: =C36/C38 -> 0.039538316 | D44: =D36/D38 -> 0.029293437 | E44: =E36/E38 -> 0.041454302 | F44: =F36/F38 -> 0.060707158 | G44: =G36/G38 -> 0.035146444 | H44: =H36/H38 -> 0.033420708 | I44: =I36/I38 -> 0.036190733 | J44: =J36/J38 -> 0.041101947 | ... L44: =L36/L38 -> 0.044234103
B45: Volume Sold (Toll Manufacturing) | C45: =C37/C38 -> 0.29936812 | D45: =D37/D38 -> 0.36122286 | E45: =E37/E38 -> 0.59682053 | F45: =F37/F38 -> 0.55003514 | G45: =G37/G38 -> 0.5665272 | H45: =H37/H38 -> 0.52948886 | I45: =I37/I38 -> 0.54071326 | J45: =J37/J38 -> 0.54283797 | ... L45: =L37/L38 -> 0.53690966
...

Sheet BS-Breakdown
B1: Assest Breakdown
B2: Non-Current Assets Breakdown
B3: Fixed Assets Breakdown
B4: Beginning Balance | C4: 2020 | D4: 2021 | E4: 2022 | F4: 2023 | G4: 2024 | H4: 2025 | I4: 2026 | J4: 2027 | K4: 2028 | L4: 2029
B5: Freehold Land | C5: 18.637425 | D5: =C55 -> 18.637425 | E5: =D55 -> 18.637425 | F5: =E55 -> 18.637425 | G5: =F55 -> 18.637425 | H5: =G55 -> 18.637425 | I5: =H55 -> 18.637425 | J5: =I55 -> 18.637425 | K5: =J55 -> 18.637425 | L5: =K55 -> 18.637425
B6: Buildings | C6: 227.83557 | D6: =C56 -> 257.22539 | E6: =D56 -> 273.34111 | F6: =E56 -> 279.17253 | G6: =F56 -> 288.43279 | H6: =G56 -> 294.76843 | I6: =H56 -> 298.61083 | J6: =I56 -> 302.95727 | K6: =J56 -> 307.62968 | L6: =K56 -> 312.13581
B7: Machinery & equipment | C7: 313.60369 | D7: =C57 -> 397.71197 | E7: =D57 -> 414.7735 | F7: =E57 -> 444.85959 | G7: =F57 -> 482.79418 | H7: =G57 -> 530.79784 | I7: =H57 -> 543.39925 | J7: =I57 -> 555.9576 | K7: =J57 -> 569.59003 | L7: =K57 -> 583.62123
B8: Transportation & dragging equipment | C8: 12.411128 | D8: =C58 -> 13.025828 | E8: =D58 -> 13.369898 | F8: =E58 -> 16.305904 | G8: =F58 -> 16.060164 | H8: =G58 -> 18.226904 | I8: =H58 -> 19.532715 | J8: =I58 -> 20.932076 | K8: =J58 -> 22.43169 | L8: =K58 -> 24.03874
B9: Laboratory equipment | C9: 17.129924 | D9: =C59 -> 20.292443 | E9: =D59 -> 28.261762 | F9: =E59 -> 31.982677 | G9: =F59 -> 35.186599 | H9: =G59 -> 35.726446 | I9: =H59 -> 36.274576 | J9: =I59 -> 36.831115 | K9: =J59 -> 37.396193 | L9: =K59 -> 37.96994
B10: Tools | C10: 3.754591 | D10: =C60 -> 5.689305 | E10: =D60 -> 6.022977 | F10: =E60 -> 7.345392 | G10: =F60 -> 11.571461 | H10: =G60 -> 14.797847 | I10: =H60 -> 18.992541 | J10: =I60 -> 24.376291 | K10: =J60 -> 31.286154 | L10: =K60 -> 40.154732
B11: Office furniture & fixtures | C11: 21.797612 | D11: =C61 -> 25.385313 | E11: =D61 -> 29.123411 | F11: =E61 -> 33.1114 | G11: =F61 -> 39.423718 | H11: =G61 -> 46.76137 | I11: =H61 -> 54.226933 | J11: =I61 -> 62.88439 | K11: =J61 -> 72.924032 | L11: =K61 -> 84.566525
B12: Assets under construction | C12: 66.327646 | D12: =C62 -> 26.589818 | E12: =D62 -> 27.041385 | F12: =E62 -> 12.858215 | G12: =F62 -> 38.090575 | H12: =G62 -> 33.464541 | I12: =H62 -> 56.759477 | J12: =I62 -> 96.270204 | K12: =J62 -> 163.28467 | L12: =K62 -> 276.94843
B13: Total Beginning Balance | C13: =SUM(C5:C12) -> 681.49759 | D13: =SUM(D5:D12) -> 764.55749 | E13: =SUM(E5:E12) -> 810.57147 | F13: =SUM(F5:F12) -> 844.27314 | G13: =SUM(G5:G12) -> 930.19691 | H13: =SUM(H5:H12) -> 993.18081 | I13: =SUM(I5:I12) -> 1046.4337 | J13: =SUM(J5:J12) -> 1118.8464 | ... L13: =SUM(L5:L12) -> 1378.0728
B14: Additions
B15: =B5 -> Freehold Land | C15: 0 | D15: 0 | E15: 0 | F15: 0 | G15: 0 | H15: =H25*H5 -> 0 | I15: =I25*I5 -> 0 | J15: =J25*J5 -> 0 | K15: =K25*K5 -> 0 | L15: =L25*L5 -> 0
B16: =B6 -> Buildings | C16: 6.992398 | D16: 2.628798 | E16: 5.274519 | F16: 4.79919 | G16: 3.75981 | H16: =H26*H6 -> 3.842397 | I16: =I26*I6 -> 4.3464404 | J16: =J26*J6 -> 4.6724123 | K16: =K26*K6 -> 4.5061346 | L16: =L26*L6 -> 4.4133972
B17: =B7 -> Machinery & equipment | C17: 8.432595 | D17: 6.387704 | E17: 9.935733 | F17: 5.093589 | G17: 19.479544 | H17: =H27*H7 -> 12.601402 | I17: =I27*I7 -> 12.558349 | J17: =J27*J7 -> 13.632437 | K17: =K27*K7 -> 14.031195 | L17: =L27*L7 -> 15.915726
B18: =B8 -> Transportation & dragging equipment | C18: 0.6815 | D18: 0.34407 | E18: 1.898136 | F18: 0 | G18: 2.16674 | H18: =H28*H8 -> 1.3058106 | I18: =I28*I8 -> 1.3993614 | J18: =J28*J8 -> 1.4996143 | K18: =K28*K8 -> 1.6070496 | L18: =L28*L8 -> 1.7221817
B19: =B9 -> Laboratory equipment | C19: 2.974732 | D19: 3.454965 | E19: 2.181576 | F19: 3.203922 | G19: 0.539847 | H19: =H29*H9 -> 0.54812955 | I19: =I29*I9 -> 0.55653918 | J19: =J29*J9 -> 0.56507782 | K19: =K29*K9 -> 0.57374748 | L19: =L29*L9 -> 0.58255014
B20: =B10 -> Tools | C20: 1.293386 | D20: 0.357601 | E20: 1.333683 | F20: 4.226069 | G20: 3.280122 | H20: =H30*H10 -> 4.1946945 | I20: =I30*I10 -> 5.38375 | J20: =J30*J10 -> 6.909863 | K20: =K30*K10 -> 8.8685779 | L20: =L30*L10 -> 11.382523
B21: =B11 -> Office furniture & fixtures | C21: 4.572201 | D21: 1.310762 | E21: 4.145679 | F21: 5.345713 | G21: 9.18869 | H21: =H31*H11 -> 7.4655629 | I21: =I31*I11 -> 8.6574576 | J21: =J31*J11 -> 10.039641 | K21: =K31*K11 -> 11.642493 | L21: =L31*L11 -> 13.501245
B22: =B12 -> Assets under construction | C22: 60.038349 | D22: 38.187101 | E22: 9.606254 | F22: 68.376758 | G22: 26.515155 | H22: =H32*H12 -> 23.294936 | I22: =I32*I12 -> 39.510727 | J22: =J32*J12 -> 67.014462 | K22: =K32*K12 -> 113.66377 | L22: =L32*L12 -> 192.78603
B23: Total Additions | C23: =SUM(C15:C22) -> 84.985161 | D23: =SUM(D15:D22) -> 52.671001 | E23: =SUM(E15:E22) -> 34.37558 | F23: =SUM(F15:F22) -> 91.045241 | G23: =SUM(G15:G22) -> 64.929908 | H23: =SUM(H15:H22) -> 53.252932 | I23: =SUM(I15:I22) -> 72.412625 | J23: =SUM(J15:J22) -> 104.33351 | ... L23: =SUM(L15:L22) -> 240.30365
B25: =B15 -> Freehold Land | C25: =C15/C5 -> 0 | D25: =D15/D5 -> 0 | E25: =E15/E5 -> 0 | F25: =F15/F5 -> 0 | G25: =G15/G5 -> 0 | H25: =G25 -> 0 | I25: =H25 -> 0 | J25: =I25 -> 0 | K25: =J25 -> 0 | L25: =K25 -> 0
B26: =B16 -> Buildings | C26: =C16/C6 -> 0.030690545 | D26: =D16/D6 -> 0.010219823 | E26: =E16/E6 -> 0.019296472 | F26: =F16/F6 -> 0.017190767 | G26: =G16/G6 -> 0.013035307 | H26: =G26 -> 0.013035307 | I26: =AVERAGE(D26:H26) -> 0.014555535 | J26: =AVERAGE(E26:I26) -> 0.015422678 | K26: =AVERAGE(F26:J26) -> 0.014647919 | L26: =AVERAGE(G26:K26) -> 0.014139349
B27: =B17 -> Machinery & equipment | C27: =C17/C7 -> 0.026889336 | D27: =D17/D7 -> 0.016061131 | E27: =E17/E7 -> 0.023954599 | F27: =F17/F7 -> 0.01144988 | G27: =G17/G7 -> 0.040347512 | H27: =AVERAGE(C27:G27) -> 0.023740492 | I27: =AVERAGE(D27:H27) -> 0.023110723 | J27: =AVERAGE(E27:I27) -> 0.024520641 | K27: =AVERAGE(F27:J27) -> 0.02463385 | L27: =AVERAGE(G27:K27) -> 0.027270644
B28: =B18 -> Transportation & dragging equipment | C28: =C18/C8 -> 0.0549104 | D28: =D18/D8 -> 0.026414444 | E28: =E18/E8 -> 0.14197087 | F28: =F18/F8 -> 0 | G28: =G18/G8 -> 0.13491394 | H28: =AVERAGE(C28:G28) -> 0.07164193 | I28: =H28 -> 0.07164193 | J28: =I28 -> 0.07164193 | K28: =J28 -> 0.07164193 | L28: =K28 -> 0.07164193
B29: =B19 -> Laboratory equipment | C29: =C19/C9 -> 0.17365705 | D29: =D19/D9 -> 0.1702587 | E29: =E19/E9 -> 0.07719179 | F29: =F19/F9 -> 0.10017679 | G29: =G19/G9 -> 0.015342404 | H29: =G29 -> 0.015342404 | I29: =H29 -> 0.015342404 | J29: =I29 -> 0.015342404 | K29: =J29 -> 0.015342404 | L29: =K29 -> 0.015342404
B30: =B20 -> Tools | C30: =C20/C10 -> 0.3444812 | D30: =D20/D10 -> 0.062854953 | E30: =E20/E10 -> 0.22143252 | F30: =F20/F10 -> 0.57533607 | G30: =G20/G10 -> 0.28346654 | H30: =G30 -> 0.28346654 | I30: =H30 -> 0.28346654 | J30: =I30 -> 0.28346654 | K30: =J30 -> 0.28346654 | L30: =K30 -> 0.28346654
B31: =B21 -> Office furniture & fixtures | C31: =C21/C11 -> 0.20975697 | D31: =D21/D11 -> 0.05163466 | E31: =E21/E11 -> 0.14234868 | F31: =F21/F11 -> 0.1614463 | G31: =G21/G11 -> 0.23307518 | H31: =AVERAGE(C31:G31) -> 0.15965236 | I31: =H31 -> 0.15965236 | J31: =I31 -> 0.15965236 | K31: =J31 -> 0.15965236 | L31: =K31 -> 0.15965236
B32: =B22 -> Assets under construction | C32: =C22/C12 -> 0.90517835 | D32: =D22/D12 -> 1.436155 | E32: =E22/E12 -> 0.35524268 | F32: =F22/F12 -> 5.3177488 | G32: =G22/G12 -> 0.69610803 | H32: =G32 -> 0.69610803 | I32: =H32 -> 0.69610803 | J32: =I32 -> 0.69610803 | K32: =J32 -> 0.69610803 | L32: =K32 -> 0.69610803
B34: Transferred from Sales under Construction
B35: =B15 -> Freehold Land | C35: 0 | D35: 0 | E35: 0 | F35: 0 | G35: 0
B36: =B16 -> Buildings | C36: 22.397417 | D36: 13.48692 | E36: 0.556909 | F36: 4.461068 | G36: 2.575827
B37: =B17 -> Machinery & equipment | C37: 76.089143 | D37: 13.6396 | E37: 20.329505 | F37: 37.268407 | G37: 28.565362
B38: =B18 -> Transportation & dragging equipment | C38: 0 | D38: 0 | E38: 1.03787 | F38: 0 | G38: 0
B39: =B19 -> Laboratory equipment | C39: 0.526239 | D39: 7.93813 | E39: 1.811035 | F39: 0 | G39: 0
B40: =B20 -> Tools | C40: 0.645928 | D40: 0 | E40: 0 | F40: 0 | G40: 0
B41: =B21 -> Office furniture & fixtures | C41: 0.11745 | D41: 2.670884 | E41: 0.054105 | F41: 1.414923 | G41: 0
B42: =B22 -> Assets under construction | C42: -99.776177 | D42: -37.735534 | E42: -23.789424 | F42: -43.144398 | G42: -31.141189
...

Sheet Assumptions
A2: Economy & Market Assumptions | B2: Scale | C2: 2020 | D2: =C2+1 -> 2021 | E2: =D2+1 -> 2022 | F2: =E2+1 -> 2023 | G2: =F2+1 -> 2024 | H2: =G2+1 -> 2025 | I2: =H2+1 -> 2026 | J2: =I2+1 -> 2027 | K2: =J2+1 -> 2028 | L2: =K2+1 -> 2029
A3: World Inflation | B3: % | C3: 0.033 | D3: 0.047 | E3: 0.087 | F3: 0.067 | G3: 0.058 | H3: 0.042 | I3: 0.037 | J3: 0.034 | K3: 0.033 | L3: 0.032
A4: MENA Inflation | B4: % | C4: 0.102 | D4: 0.117 | E4: 0.132 | F4: 0.117 | G4: 0.109 | H4: 0.104 | I4: 0.102 | J4: 0.087 | K4: 0.077 | L4: 0.069 | M4: Forecasting Exports (ASP)
A5: Egypt Inflation | B5: % | C5: 0.057 | D5: 0.049 | E5: 0.132 | F5: 0.357 | G5: 0.275 | H5: 0.149 | I5: 0.113 | J5: 0.083 | K5: 0.055 | L5: 0.053 | M5: anhy asah? correlation or R2
A6: Central Bank Policy Rate | B6: % | C6: 0.10262 | D6: 0.1004 | E6: 0.1633 | F6: 0.19365 | G6: 0.27335 | H6: 0.21 | I6: 0.1125 | J6: 0.0825 | K6: 0.0825 | L6: 0.0825
A7: Borrowing rate | B7: % | C7: =C6-1% -> 0.09262 | D7: =D6-1% -> 0.0904 | E7: =E6-1% -> 0.1533 | F7: =F6-1% -> 0.18365 | G7: =G6-1% -> 0.26335 | H7: =H6-1% -> 0.2 | I7: =I6-1% -> 0.1025 | J7: =J6-1% -> 0.0725 | ... L7: =L6-1% -> 0.0725
A8: Real Interest Rate | B8: % | C8: =C6-C5 -> 0.04562 | D8: =D6-D5 -> 0.0514 | E8: =E6-E5 -> 0.0313 | F8: =F6-F5 -> -0.16335 | G8: =G6-G5 -> -0.00165 | H8: =H6-H5 -> 0.061 | I8: =I6-I5 -> -0.0005 | J8: =J6-J5 -> -0.0005 | ... L8: =L6-L5 -> 0.0295
A9: Exchange Rate Per USD | B9: EGP | C9: 15.6842 | D9: 15.6611 | E9: 24.6894 | F9: 30.8414 | G9: 50.7866 | H9: 47.09 | I9: 49.24 | J9: 50.23 | K9: 51.23 | L9: 52.26 | M9: used in forecasting asp tender, ps,
A10: Nominal GDP USD | B10: USDbn | C10: 383.82 | D10: 424.67 | E10: 476.75 | F10: 395.93 | G10: 389.06 | H10: 324.5 | I10: 382.5 | J10: 422.3 | K10: 463.4 | L10: 508.5
A11: Nominal GDP | B11: EGPbn | C11: =C10*C9 -> 6019.9096 | D11: =D10*D9 -> 6650.7993 | E11: =E10*E9 -> 11770.671 | F11: =F10*F9 -> 12211.036 | G11: =G10*G9 -> 19759.035 | H11: 15822.62 | I11: 18834.3 | J11: 21212.129 | K11: 23739.982 | L11: 26574.21
A12: Real GDP | B12: EGPTn | C12: =C25/C19 -> 6159.4495 | D12: =D25/D19 -> 6679.2638 | E12: =E25/E19 -> 7853.1288 | F12: =F25/F19 -> 10158.539 | G12: =G25/G19 -> 13942.892 | H12: =H25/H19 -> 16421.508 | I12: =I25/I19 -> 19170.417 | J12: =J25/J19 -> 21453.438 | ... L12: =L25/L19 -> 26720.069
A13: Real GDP | B13: % | C13: 0.03573 | D13: 0.03253 | E13: 0.06653 | F13: 0.03759 | G13: 0.02672 | H13: 0.043 | I13: 0.045 | J13: 0.047 | K13: 0.049 | L13: 0.051
A14: MENA GDP Per Capita | B14: USD K | C14: 9.79 | D14: 12.01 | E14: 14.42 | F14: 13.83 | G14: 13.87 | H14: 13.79 | I14: 14.28 | J14: 14.85 | K14: 15.43 | L14: 15.97
H15: =150/12 -> 12.5 | L15: =L11/K11-1 -> 0.11938627
A17: Industry Assumptions | B17: Scale | C17: 2020 | D17: =C17+1 -> 2021 | E17: =D17+1 -> 2022 | F17: =E17+1 -> 2023 | G17: =F17+1 -> 2024 | H17: =G17+1 -> 2025 | I17: =H17+1 -> 2026 | J17: =I17+1 -> 2027 | K17: =J17+1 -> 2028 | L17: =K17+1 -> 2029
A18: Pharmaceutical Sales, % of health expenditure | B18: % | C18: 0.252 | D18: 0.354 | E18: 0.347 | F18: 0.385 | G18: 0.37 | H18: 0.391 | I18: 0.368 | J18: 0.35 | K18: 0.332 | L18: 0.316
A19: Pharmaceutical Sales, % of GDP | B19: % | C19: 0.0109 | D19: 0.0163 | E19: 0.0163 | F19: 0.0178 | G19: 0.0166 | H19: 0.0179 | I19: 0.0168 | J19: 0.016 | K19: 0.0152 | L19: 0.0144
A20: Pharmaceutical Sales, EGP per capita | B20: EGP | C20: 624.7 | D20: 996.4 | E20: 1153.3 | F20: 1604.2 | G20: 2021.7 | H20: 2528 | I20: 2728 | J20: 2864.3 | K20: 2990.3 | L20: 3118.5 | M20: used in forecasting vs toll,ps,X
A21: Patented Drug Sales | B21: EGPbn | C21: 17.928 | D21: 26.168 | E21: 28.108 | F21: 37.408 | G21: 39.347 | H21: 56.136 | I21: 61.068 | J21: 64.743 | K21: 68.226 | L21: 71.804
A22: Generic drug sales, EGPbn | B22: EGPbn | C22: 38.046 | D22: 66.262 | E22: 81.023 | F22: 117.534 | G22: 145.815 | H22: 187.838 | I22: 206.456 | J22: 220.734 | K22: 234.584 | L22: 248.983
A23: Prescription drug sales | B23: EGPbn | C23: =+C21+C22 -> 55.974 | D23: =+D21+D22 -> 92.43 | E23: =+E21+E22 -> 109.131 | F23: =+F21+F22 -> 154.942 | G23: =+G21+G22 -> 185.162 | H23: =+H21+H22 -> 243.974 | I23: =+I21+I22 -> 267.524 | J23: =+J21+J22 -> 285.477 | ... L23: =+L21+L22 -> 320.787
A24: OTC medicine sales, EGPbn (over-the-counter) | B24: EGPbn | C24: 11.164 | D24: 16.442 | E24: 18.875 | F24: 25.88 | G24: 46.29 | H24: 49.971 | I24: 54.539 | J24: 57.778 | K24: 60.841 | L24: 63.982 | M24: =_xlfn.RRI(4,H25,L25) -> 0.069629813
A25: Total Pharmaceutical Sales | B25: EGPbn | C25: =+C23+C24 -> 67.138 | D25: =+D23+D24 -> 108.872 | E25: =+E23+E24 -> 128.006 | F25: =+F23+F24 -> 180.822 | G25: =+G23+G24 -> 231.452 | H25: =+H23+H24 -> 293.945 | I25: =+I23+I24 -> 322.063 | J25: =+J23+J24 -> 343.255 | ... L25: =+L23+L24 -> 384.769 | M25: Used in CAGR | O25: Y.o.Y | P25: =H25/G25-1 -> 0.27000415 | Q25: leh el market ahsn mn rmda?
A26: Health Expenditure | B26: EGPbn | C26: =C25/C18 -> 266.42063 | D26: =D25/D18 -> 307.54802 | E26: =E25/E18 -> 368.89337 | F26: =F25/F18 -> 469.66753 | G26: =G25/G18 -> 625.54595 | H26: =H25/H18 -> 751.77749 | I26: =I25/I18 -> 875.1712 | J26: =J25/J18 -> 980.72857 | ... L26: =L25/L18 -> 1217.6234 | M26: used in forecasting vs tender
G27: =_xlfn.RRI(COLUMNS(C26:G26),C26,G26) -> 0.18614633
A29: Patented Drug Sales (%) | B29: % | C29: =C21/C23 -> 0.32029156 | D29: =D21/D23 -> 0.28311154 | E29: =E21/E23 -> 0.25756201 | F29: =F21/F23 -> 0.24143228 | G29: =G21/G23 -> 0.21250041 | H29: =H21/H23 -> 0.23009009 | I29: =I21/I23 -> 0.22827111 | J29: =J21/J23 -> 0.22678885 | ... L29: =L21/L23 -> 0.223837
A30: Generic drug sales, EGPbn (%) | B30: % | C30: =C22/C23 -> 0.67970844 | D30: =D22/D23 -> 0.71688846 | E30: =E22/E23 -> 0.74243799 | F30: =F22/F23 -> 0.75856772 | G30: =G22/G23 -> 0.78749959 | H30: =H22/H23 -> 0.76990991 | I30: =I22/I23 -> 0.77172889 | J30: =J22/J23 -> 0.77321115 | ... L30: =L22/L23 -> 0.776163
A31: Prescription drug sales | B31: % | C31: =SUM(C29:C30) -> 1 | D31: =SUM(D29:D30) -> 1 | E31: =SUM(E29:E30) -> 1 | F31: =SUM(F29:F30) -> 1 | G31: =SUM(G29:G30) -> 1 | H31: =SUM(H29:H30) -> 1 | I31: =SUM(I29:I30) -> 1 | J31: =SUM(J29:J30) -> 1 | ... L31: =SUM(L29:L30) -> 1
A33: Pharmaceutical Trade Assumptions | B33: Scale | C33: 2020 | D33: =C33+1 -> 2021 | E33: =D33+1 -> 2022 | F33: =E33+1 -> 2023 | G33: =F33+1 -> 2024 | H33: =G33+1 -> 2025 | I33: =H33+1 -> 2026 | J33: =I33+1 -> 2027 | K33: =J33+1 -> 2028 | L33: =K33+1 -> 2029
A34: Pharmaceutical Exports | B34: EGPMn | C34: 5235.9 | D34: 6082.4 | E34: 6977.92 | F34: 8812.17 | G34: 13984.52 | H34: 17327.71 | I34: 19367.68 | J34: 21553.67 | K34: 23838.22 | L34: 26257.23
A35: Pharmaceutical Imports | B35: EGPMn | C35: 22578.1 | D35: 23687.68 | E35: 24889.61 | F35: 108580.22 | G35: 138982.68 | H35: 163989.09 | I35: 172939.98 | J35: 180968.15 | K35: 189137.01 | L35: 197804.9 | N35: CAGR Phrmaceutical | Q35: =_xlfn.RRI(4,H25,L25) -> 0.069629813 | R35: For cosmetic forecasting
A36: Pharmaceutical Trade Balance | B36: EGPMn | C36: =C34-C35 -> -17342.2 | D36: =D34-D35 -> -17605.28 | E36: =E34-E35 -> -17911.69 | F36: =F34-F35 -> -99768.05 | G36: =G34-G35 -> -124998.16 | H36: =H34-H35 -> -146661.38 | I36: =I34-I35 -> -153572.3 | J36: =J34-J35 -> -159414.48 | ... L36: =L34-L35 -> -171547.67 | N36: CAGR Non-essentials | Q36: =_xlfn.RRI(4,H44,L44) -> 0.11760104
D37: =D34/D$36 -> -0.34548726 | N37: CAGR personal care | Q37: =_xlfn.RRI(4,H50,L50) -> 0.1143772
A38: Pharmaceutical Exports (%) | B38: % | C38: =C34/C$36 -> -0.30191671 | E38: =E34/E$36 -> -0.38957351 | F38: =F34/F$36 -> -0.088326573 | G38: =G34/G$36 -> -0.11187781 | H38: =H34/H$36 -> -0.11814774 | I38: =I34/I$36 -> -0.12611441 | J38: =J34/J$36 -> -0.13520522 | K38: =K34/K$36 -> -0.14421291 | L38: =L34/L$36 -> -0.15306084
A39: Pharmaceutical Imports (%) | B39: % | C39: =-C35/C$36 -> 1.3019167 | D39: =-D35/D$36 -> 1.3454873 | E39: =-E35/E$36 -> 1.3895735 | F39: =-F35/F$36 -> 1.0883266 | G39: =-G35/G$36 -> 1.1118778 | H39: =-H35/H$36 -> 1.1181477 | I39: =-I35/I$36 -> 1.1261144 | J39: =-J35/J$36 -> 1.1352052 | ... L39: =-L35/L$36 -> 1.1530608
A40: Pharmaceutical Trade Balance (%) | B40: % | C40: =SUM(C38:C39) -> 1 | D40: =SUM(D37:D39) -> 1 | E40: =SUM(E38:E39) -> 1 | F40: =SUM(F38:F39) -> 1 | G40: =SUM(G38:G39) -> 1 | H40: =SUM(H38:H39) -> 1 | I40: =SUM(I38:I39) -> 1 | J40: =SUM(J38:J39) -> 1 | K40: =SUM(K38:K39) -> 1 | L40: =SUM(L38:L39) -> 1
I41: =FORECAST(,'IS- Breakdown'!F37:H37,Assumptions!F20:H20) -> 31.674276
A42: Consumer Spending Assumptions | B42: Scale | C42: 2020 | D42: =C42+1 -> 2021 | E42: =D42+1 -> 2022 | F42: =E42+1 -> 2023 | G42: =F42+1 -> 2024 | H42: =G42+1 -> 2025 | I42: =H42+1 -> 2026 | J42: =I42+1 -> 2027 | K42: =J42+1 -> 2028 | L42: =K42+1 -> 2029
A43: Household Essential Spending | B43: EGPBn | C43: 1458 | D43: 1653.5 | E43: 4294.4 | F43: 5695.6 | G43: 8107.2 | H43: 9834.2 | I43: 11345.7 | J43: 12609.9 | K43: 14013.6 | L43: 15572.1
A44: Household Non-Essential Spending | B44: EGPBn | C44: 793 | D44: 907.4 | E44: 2176.9 | F44: 2824.1 | G44: 3936.2 | H44: 4733.6 | I44: 5431.8 | J44: 6016.3 | K44: 6665 | L44: 7384.8 | M44: Used in CAGR
...

Sheet Revenue Bridge
B1: Revenue Bridge
B3: Average Selling Prices | C3: 2020 | D3: 2021 | E3: 2022 | F3: 2023 | G3: 2024 | H3: =G3+1 -> 2025 | I3: =H3+1 -> 2026 | J3: =I3+1 -> 2027 | K3: =J3+1 -> 2028 | L3: =K3+1 -> 2029
B4: ASP (Tender) | C4: ='IS- Breakdown'!C$48 -> 6.6068439 | D4: ='IS- Breakdown'!D$48 -> 9.4854414 | E4: ='IS- Breakdown'!E$48 -> 9.8464592 | F4: ='IS- Breakdown'!F$48 -> 14.463395 | G4: ='IS- Breakdown'!G$48 -> 29.18895 | H4: ='IS- Breakdown'!H$48 -> 28.89028 | I4: ='IS- Breakdown'!I$48 -> 32.154882 | J4: ='IS- Breakdown'!J$48 -> 34.823737 | ... L4: ='IS- Breakdown'!L$48 -> 38.686212
B5: ASP (Private Sales) | C5: ='IS- Breakdown'!C49 -> 24.334552 | D5: ='IS- Breakdown'!D49 -> 26.230105 | E5: ='IS- Breakdown'!E49 -> 30.029275 | F5: ='IS- Breakdown'!F49 -> 44.582554 | G5: ='IS- Breakdown'!G49 -> 55.903542 | H5: ='IS- Breakdown'!H$49 -> 61.348156 | I5: ='IS- Breakdown'!I$49 -> 68.280498 | J5: ='IS- Breakdown'!J$49 -> 73.947779 | K5: ='IS- Breakdown'!K$49 -> 78.014907 | L5: ='IS- Breakdown'!L$49 -> 82.149697
B6: ASP (Exports) | C6: ='IS- Breakdown'!C50 -> 14.563648 | D6: ='IS- Breakdown'!D50 -> 31.428071 | E6: ='IS- Breakdown'!E50 -> 17.72451 | F6: ='IS- Breakdown'!F50 -> 25.728593 | G6: ='IS- Breakdown'!G50 -> 33.857702 | H6: ='IS- Breakdown'!H$50 -> 33.751955 | I6: ='IS- Breakdown'!I$50 -> 37.194655 | J6: ='IS- Breakdown'!J$50 -> 40.43059 | K6: ='IS- Breakdown'!K$50 -> 43.543745 | L6: ='IS- Breakdown'!L$50 -> 46.548264
B7: ASP (Toll Manufacturing) | C7: ='IS- Breakdown'!C51 -> 1.9581577 | D7: ='IS- Breakdown'!D51 -> 2.2475304 | E7: ='IS- Breakdown'!E51 -> 1.5308493 | F7: ='IS- Breakdown'!F51 -> 2.1111915 | G7: ='IS- Breakdown'!G51 -> 2.6863465 | H7: ='IS- Breakdown'!H$51 -> 3.5202408 | I7: ='IS- Breakdown'!I$51 -> 3.918028 | J7: ='IS- Breakdown'!J$51 -> 4.2432244 | K7: ='IS- Breakdown'!K$51 -> 4.4766017 | L7: ='IS- Breakdown'!L$51 -> 4.7138616
B9: Volume Sold | C9: 2020 | D9: 2021 | E9: 2022 | F9: 2023 | G9: 2024 | H9: =G9+1 -> 2025 | I9: =H9+1 -> 2026 | J9: =I9+1 -> 2027 | K9: =J9+1 -> 2028 | L9: =K9+1 -> 2029
B10: Volume Sold (Tender) | C10: ='IS- Breakdown'!C34 -> 30.224 | D10: ='IS- Breakdown'!D34 -> 26.566 | E10: ='IS- Breakdown'!E34 -> 16.3278 | F10: ='IS- Breakdown'!F34 -> 13.1 | G10: ='IS- Breakdown'!G34 -> 8.1 | H10: ='IS- Breakdown'!H$34 -> 18.5 | I10: ='IS- Breakdown'!I$34 -> 17.688051 | J10: ='IS- Breakdown'!J$34 -> 18.152606 | K10: ='IS- Breakdown'!K$34 -> 18.161376 | L10: ='IS- Breakdown'!L$34 -> 19.190501
B11: Volume Sold (Private Sales) | C11: ='IS- Breakdown'!C35 -> 27.11 | D11: ='IS- Breakdown'!D35 -> 31.608 | E11: ='IS- Breakdown'!E35 -> 36.106 | F11: ='IS- Breakdown'!F35 -> 31.8203 | G11: ='IS- Breakdown'!G35 -> 39.5 | H11: ='IS- Breakdown'!H$35 -> 48.2 | I11: ='IS- Breakdown'!I$35 -> 47.663129 | J11: ='IS- Breakdown'!J$35 -> 48.877726 | K11: ='IS- Breakdown'!K$35 -> 50.186869 | L11: ='IS- Breakdown'!L$35 -> 53.046985
B12: Volume Sold (Exports) | C12: ='IS- Breakdown'!C36 -> 3.429 | D12: ='IS- Breakdown'!D36 -> 2.796 | E12: ='IS- Breakdown'!E36 -> 6.009 | F12: ='IS- Breakdown'!F36 -> 7.0056 | G12: ='IS- Breakdown'!G36 -> 4.2 | H12: ='IS- Breakdown'!H$36 -> 5.1 | I12: ='IS- Breakdown'!I$36 -> 5.590001 | J12: ='IS- Breakdown'!J$36 -> 6.6218252 | K12: ='IS- Breakdown'!K$36 -> 7.0650053 | L12: ='IS- Breakdown'!L$36 -> 7.6287759
B13: Volume Sold (Toll Manufacturing) | C13: ='IS- Breakdown'!C37 -> 25.963 | D13: ='IS- Breakdown'!D37 -> 34.478 | E13: ='IS- Breakdown'!E37 -> 86.512 | F13: ='IS- Breakdown'!F37 -> 63.474 | G13: ='IS- Breakdown'!G37 -> 67.7 | H13: ='IS- Breakdown'!H$37 -> 80.8 | I13: ='IS- Breakdown'!I$37 -> 83.518277 | J13: ='IS- Breakdown'!J$37 -> 87.45518 | K13: ='IS- Breakdown'!K$37 -> 89.405031 | L13: ='IS- Breakdown'!L$37 -> 92.597413
B14: Total | C14: =SUM(C10:C13) -> 86.726 | D14: =SUM(D10:D13) -> 95.448 | E14: =SUM(E10:E13) -> 144.9548 | F14: =SUM(F10:F13) -> 115.3999 | G14: =SUM(G10:G13) -> 119.5 | H14: =SUM(H10:H13) -> 152.6 | I14: =SUM(I10:I13) -> 154.45946 | J14: =SUM(J10:J13) -> 161.10734 | ... L14: =SUM(L10:L13) -> 172.46367
B16: Sales | C16: 2020 | D16: 2021 | E16: 2022 | F16: 2023 | G16: 2024 | H16: =G16+1 -> 2025 | I16: =H16+1 -> 2026 | J16: =I16+1 -> 2027 | K16: =J16+1 -> 2028 | L16: =K16+1 -> 2029
B17: Sales (Tender) | C17: =C$4*C$10 -> 199.68525 | D17: =D$4*D$10 -> 251.99024 | E17: =E$4*E$10 -> 160.77102 | F17: =F$4*F$10 -> 189.47047 | G17: =G$4*G$10 -> 236.4305 | H17: =H4*H10 -> 534.47018 | I17: =I4*I10 -> 568.75719 | J17: =J4*J10 -> 632.14158 | K17: =K4*K10 -> 667.23157 | L17: =L4*L10 -> 742.40776
B18: Sales (Private Sales) | C18: =C$5*C$11 -> 659.7097 | D18: =D$5*D$11 -> 829.08115 | E18: =E$5*E$11 -> 1084.237 | F18: =F$5*F$11 -> 1418.6302 | G18: =G$5*G$11 -> 2208.1899 | H18: =H5*H11 -> 2956.9811 | I18: =I5*I11 -> 3254.4621 | J18: =J5*J11 -> 3614.3993 | K18: =K5*K11 -> 3915.3239 | L18: =L5*L11 -> 4357.7937
B19: Sales (Exports) | C19: =C$6*C12 -> 49.93875 | D19: =D$6*D12 -> 87.872886 | E19: =E$6*E12 -> 106.50658 | F19: =F$6*F12 -> 180.24423 | G19: =G$6*G12 -> 142.20235 | H19: =H6*H12 -> 172.13497 | I19: =I6*I12 -> 207.91816 | J19: =J6*J12 -> 267.7243 | K19: =K6*K12 -> 307.63679 | L19: =L6*L12 -> 355.10627
B20: Sales (Toll Manufacturing) | C20: =C$7*C13 -> 50.839648 | D20: =D$7*D13 -> 77.490353 | E20: =E$7*E13 -> 132.43683 | F20: =F$7*F13 -> 134.00577 | G20: =G$7*G13 -> 181.86566 | H20: =H7*H13 -> 284.43546 | I20: =I7*I13 -> 327.22695 | J20: =J7*J13 -> 371.09195 | K20: =K7*K13 -> 400.23072 | L20: =L7*L13 -> 436.49139
B21: Total | C21: =SUM(C$17:C$20) -> 960.17335 | D21: =SUM(D$17:D$20) -> 1246.4346 | E21: =SUM(E$17:E$20) -> 1483.9514 | F21: =SUM(F$17:F$20) -> 1922.3507 | G21: =SUM(G$17:G$20) -> 2768.6884 | H21: =SUM(H$17:H$20) -> 3948.0217 | I21: =SUM(I$17:I$20) -> 4358.3644 | J21: =SUM(J$17:J$20) -> 4885.3571 | ... L21: =SUM(L$17:L$20) -> 5891.7992
B23: Total ASP | C23: =C21/C14 -> 11.071344 | D23: =D21/D14 -> 13.058782 | E23: =E21/E14 -> 10.237339 | F23: =F21/F14 -> 16.658166 | G23: =G21/G14 -> 23.168941 | H23: =H21/H14 -> 25.871702 | I23: =I21/I14 -> 28.216883 | J23: =J21/J14 -> 30.323617 | ... L23: =L21/L14 -> 34.162551
B25: Price Effect | C25: 2020 | D25: 2021 | E25: 2022 | F25: 2023 | G25: 2024 | H25: =G25+1 -> 2025 | I25: =H25+1 -> 2026 | J25: =I25+1 -> 2027 | K25: =J25+1 -> 2028 | L25: =K25+1 -> 2029
B26: PE (Tender) | D26: =(D4-C4)*C10 -> 87.00273 | E26: =(E4-D4)*D10 -> 9.5907999 | F26: =(F4-E4)*E10 -> 75.384401 | G26: =(G4-F4)*F10 -> 192.90478 | H26: =(H4-G4)*G10 -> -2.419231 | I26: =(I4-H4)*H10 -> 60.39513 | J26: =(J4-I4)*I10 -> 47.206847 | K26: =(K4-J4)*J10 -> 34.767787 | L26: =(L4-K4)*K10 -> 35.363273
B27: PE (Private Sales) | D27: =(D5-C5)*C11 -> 51.388442 | E27: =(E5-D5)*D11 -> 120.08416 | F27: =(F5-E5)*E11 -> 525.4607 | G27: =(G5-F5)*F11 -> 360.23725 | H27: =(H5-G5)*G11 -> 215.06224 | I27: =(I5-H5)*H11 -> 334.13887 | J27: =(J5-I5)*I11 -> 270.12036 | K27: =(K5-J5)*J11 -> 198.79196 | L27: =(L5-K5)*K11 -> 207.51217
B28: PE (Exports) | D28: =(D6-C6)*C12 -> 57.828105 | E28: =(E6-D6)*D12 -> -38.315155 | F28: =(F6-E6)*E12 -> 48.096536 | G28: =(G6-F6)*F12 -> 56.949281 | H28: =(H6-G6)*G12 -> -0.44413394 | I28: =(I6-H6)*H12 -> 17.557767 | J28: =(J6-I6)*I12 -> 18.08888 | K28: =(K6-J6)*J12 -> 20.614771 | L28: =(L6-K6)*K12 -> 21.226939
B29: PE (Toll Manufacturing) | D29: =(D7-C7)*C13 -> 7.5129837 | E29: =(E7-D7)*D13 -> -24.709731 | F29: =(F7-E7)*E13 -> 50.20657 | G29: =(G7-F7)*F13 -> 36.507387 | H29: =(H7-G7)*G13 -> 56.454645 | I29: =(I7-H7)*H13 -> 32.141207 | J29: =(J7-I7)*I13 -> 27.159837 | K29: =(K7-J7)*J13 -> 20.410057 | L29: =(L7-K7)*K13 -> 21.212228
B30: Total | C30: =SUM(C26:C29) -> 0 | D30: =SUM(D26:D29) -> 203.73226 | E30: =SUM(E26:E29) -> 66.650076 | F30: =SUM(F26:F29) -> 699.14821 | G30: =SUM(G26:G29) -> 646.59869 | H30: =SUM(H26:H29) -> 268.65352 | I30: =SUM(I26:I29) -> 444.23297 | J30: =SUM(J26:J29) -> 362.57592 | ... L30: =SUM(L26:L29) -> 285.31461
B32: Volume Effect | C32: 2020 | D32: 2021 | E32: 2022 | F32: 2023 | G32: 2024 | H32: =G32+1 -> 2025 | I32: =H32+1 -> 2026 | J32: =I32+1 -> 2027 | K32: =J32+1 -> 2028 | L32: =K32+1 -> 2029
B33: VE (Tender) | D33: =(D10-C10)*C4 -> -24.167835 | E33: =(E10-D10)*D4 -> -97.113846 | F33: =(F10-E10)*E4 -> -31.782401 | G33: =(G10-F10)*F4 -> -72.316974 | H33: =(H10-G10)*G4 -> 303.56509 | I33: =(I10-H10)*H4 -> -23.457433 | J33: =(J10-I10)*I4 -> 14.937718 | K33: =(K10-J10)*J4 -> 0.30540298 | L33: =(L10-K10)*K4 -> 37.809041
B34: VE (Private Sales) | D34: =(D11-C11)*C5 -> 109.45681 | E34: =(E11-D11)*D5 -> 117.98301 | F34: =(F11-E11)*E5 -> -128.69646 | G34: =(G11-F11)*F5 -> 342.38064 | H34: =(H11-G11)*G5 -> 486.36082 | I34: =(I11-H11)*H5 -> -32.936074 | J34: =(J11-I11)*I5 -> 82.933325 | K34: =(K11-J11)*J5 -> 96.808203 | L34: =(L11-K11)*K5 -> 223.13169
B35: VE (Exports) | D35: =(D12-C12)*C6 -> -9.2187894 | E35: =(E12-D12)*D6 -> 100.97839 | F35: =(F12-E12)*E6 -> 17.664247 | G35: =(G12-F12)*F6 -> -72.184142 | H35: =(H12-G12)*G6 -> 30.471931 | I35: =(I12-H12)*H6 -> 16.538493 | J35: =(J12-I12)*I6 -> 38.378345 | K35: =(K12-J12)*J6 -> 17.918032 | L35: =(L12-K12)*K6 -> 24.548683
B36: VE (Toll Manufacturing) | D36: =(D13-C13)*C7 -> 16.673713 | E36: =(E13-D13)*D7 -> 116.948 | F36: =(F13-E13)*E7 -> -35.267706 | G36: =(G13-F13)*F7 -> 8.9218955 | H36: =(H13-G13)*G7 -> 35.191139 | I36: =(I13-H13)*H7 -> 9.5689891 | J36: =(J13-I13)*I7 -> 15.424895 | K36: =(K13-J13)*J7 -> 8.273658 | L36: =(L13-K13)*K7 -> 14.291023
B37: Total | D37: =SUM(D33:D36) -> 92.743902 | E37: =SUM(E33:E36) -> 238.79555 | F37: =SUM(F33:F36) -> -178.08232 | G37: =SUM(G33:G36) -> 206.80142 | H37: =SUM(H33:H36) -> 855.58897 | I37: =SUM(I33:I36) -> -30.286025 | J37: =SUM(J33:J36) -> 151.67428 | K37: =SUM(K33:K36) -> 123.3053 | L37: =SUM(L33:L36) -> 299.78044
B39: Cross Effect | C39: 2020 | D39: 2021 | E39: 2022 | F39: 2023 | G39: 2024 | H39: =G39+1 -> 2025 | I39: =H39+1 -> 2026 | J39: =I39+1 -> 2027 | K39: =J39+1 -> 2028 | L39: =K39+1 -> 2029
B40: CE (Tender) | D40: =(D4-C4)*(D10-C10) -> -10.52991 | E40: =(E4-D4)*(E10-D10) -> -3.6961728 | F40: =(F4-E4)*(F10-E10) -> -14.902545 | G40: =(G4-F4)*(G10-F10) -> -73.627778 | H40: =(H4-G4)*(H10-G10) -> -3.1061731 | I40: =(I4-H4)*(I10-H10) -> -2.6506899 | J40: =(J4-I4)*(J10-I10) -> 1.2398306 | K40: =(K4-J4)*(K10-J10) -> 0.016797164 | L40: =(L4-K4)*(L10-K10) -> 2.0038792
B41: CE (Private Sales) | D41: =(D5-C5)*(D11-C11) -> 8.5261973 | E41: =(E5-D5)*(E11-D11) -> 17.088666 | F41: =(F5-E5)*(F11-E11) -> -62.370989 | G41: =(G5-F5)*(G11-F11) -> 86.941794 | H41: =(H5-G5)*(H11-G11) -> 47.368138 | I41: =(I5-H5)*(I11-H11) -> -3.7217764 | J41: =(J5-I5)*(J11-I11) -> 6.883466 | K41: =(K5-J5)*(K11-J11) -> 5.3244512 | L41: =(L5-K5)*(L11-K11) -> 11.82598
B42: CE (Exports) | D42: =(D6-C6)*(D12-C12) -> -10.675179 | E42: =(E6-D6)*(E12-D12) -> -44.02954 | F42: =(F6-E6)*(F12-E12) -> 7.9768693 | G42: =(G6-F6)*(G12-F12) -> -22.807026 | H42: =(H6-G6)*(H12-G12) -> -0.095171559 | I42: =(I6-H6)*(I12-H12) -> 1.6869263 | J42: =(J6-I6)*(J12-I12) -> 3.3389161 | K42: =(K6-J6)*(K12-J12) -> 1.3796884 | L42: =(L6-K6)*(L12-K12) -> 1.6938591
B43: CE (Toll Manufacturing) | D43: =(D7-C7)*(D13-C13) -> 2.4640086 | E43: =(E7-D7)*(E13-D13) -> -37.291785 | F43: =(F7-E7)*(F13-E13) -> -13.369925 | G43: =(G7-F7)*(G13-F13) -> 2.4306049 | H43: =(H7-G7)*(H13-G13) -> 10.924016 | I43: =(I7-H7)*(I13-H13) -> 1.0812958 | J43: =(J7-I7)*(J13-I13) -> 1.2802663 | K43: =(K7-J7)*(K13-J13) -> 0.45505119 | L43: =(L7-K7)*(L13-K13) -> 0.75742423
